Workbook

Sheet 操作パネル
A1: ▶ 新規案件作成
A2: 株式会社 LinK - 見積・原価管理システム
A3: =HYPERLINK("#案件管理!A1","📋案件管理") -> 📋案件管理 | B3: =HYPERLINK("#ダッシュボード!A1","📊ダッシュボード") -> 📊ダッシュボード | C3: =HYPERLINK("#請求管理!A1","💰請求管理") -> 💰請求管理 | D3: =HYPERLINK("#支払管理!A1","🔧支払管理") -> 🔧支払管理
A4: ■ 新規案件作成
A5: ※ 以下の情報を入力して「Claudeに依頼」で新規案件シートを作成できます
A7: 顧客ID | B7: C-001 | C7: 顧客名 | D7: =IFERROR(VLOOKUP(B7,顧客マスタ!A:C,3,FALSE),"") -> 矢島不動産管理株式会社 | F7: 敬称 | G7: =IFERROR(VLOOKUP(B7,顧客マスタ!A:D,4,FALSE),"") -> 御中
A8: 工事名 | B8: 吉野様邸 キッチンリフォーム | E8: 施工場所 | F8: 東京都港区南麻布
A9: 担当者 | B9: 吉野博 | C9: 目標粗利率 | D9: 0.25
A10: 施工住所
A12: ▼ 作成手順
A13: 1️⃣ | B13: 上の顧客ID・工事名・施工場所・担当者を入力
A14: 2️⃣ | B14: Claudeに「新規案件作成」と伝える
A15: 3️⃣ | B15: 案件テンプレートが複製され、情報が自動入力されます
A16: 4️⃣ | B16: 原価管理表に工事項目を入力→客出し金額が自動算出
A17: 5️⃣ | B17: 発注書兼請求書も同時に発行可能
A19: ■ システム構成一覧
A20: シート名 | B20: 役割 | C20: 主な用途 | D20: 備考
A21: 操作パネル | B21: コントロールセンター | C21: 新規案件作成・操作マニュアル | D21: ※このシート
A22: マスター設定 | B22: マスターデータ管理 | C22: 顧客・業者・工事カテゴリ等の登録
A23: 工事項目DB | B23: 単価データベース | C23: 全工種の単価・業者を一元管理 | D23: ★2024年統合済
A24: 業者DB | B24: 業者データベース | C24: 全業者の連絡先・支払条件
A25: 見積書 | B25: 見積作成 | C25: 顧客提出用見積書作成
A26: 実行予算 | B26: 原価管理 | C26: 実行予算の計算・利益率管理
A27: 案件管理 | B27: 案件データベース | C27: 全案件の進捗・収支・請求状況 | D27: ★中核シート
A28: ダッシュボード | B28: 経営ダッシュボード | C28: 売上・原価・利益・KPI・キャッシュフロー | D28: ★2024年拡張済
A29: 請求管理 | B29: 請求・入金管理 | C29: 請求書発行・入金消込・残額管理 | D29: ★NEW
A30: 支払管理 | B30: 発注・支払管理 | C30: 業者への発注・支払消込・未払管理 | D30: ★NEW
A31: 設計図v3 | B31: 設計ドキュメント | C31: システム設計・実装記録
A33: ■ 請求管理の使い方
A34: 🔹 概要 | B34: 請求書の発行から入金消込までを一元管理するシートです
A36: 🔹 操作手順
A37: 1️⃣ | B37: 「請求管理」シートを開く
A38: 2️⃣ | B38: B列に案件ID（P-001等）を入力 → 案件名・顧客名が自動取得
A39: 3️⃣ | B39: E列で請求種別を選択（着手金/完工金/一括/中間金/その他）
A40: 4️⃣ | B40: F列に請求日、G列に請求額を入力
A41: 5️⃣ | B41: 入金時に H列（入金日）と I列（入金額）を入力
A42: ✅ | B42: J列（残額）とK列（ステータス）が自動計算されます
B43: ※ 案件管理のX列～AC列にも自動連携されます
A45: ■ 支払管理の使い方
A46: 🔹 概要 | B46: 業者への発注・支払状況を一元管理するシートです
...

Sheet ダッシュボード
A1: CRM ダッシュボード
A2: 株式会社LinK - 営業・案件パフォーマンス分析
A3: ※ 案件管理・顧客マスタのデータをリアルタイムで集計表示します
A4: 受注金額合計 | D4: 粗利率平均 | G4: 未回収残高 | J4: キャッシュフロー
A5: =SUMIFS(案件管理!F5:F96,案件管理!I5:I96,"⑤受注")+SUMIFS(案件管理!F5:F96,案件管理!I5:I96,"⑦完工") -> 4754440 | D5: =IFERROR(AVERAGE(案件管理!H5:H96),0) -> 0.26950193 | G5: =SUM(請求管理!G:G)-SUM(請求管理!I:I) -> 627220 | J5: =SUM(請求管理!I:I)-SUM(支払管理!I:I) -> 3922220
A7: ■ KPI サマリー
A8: 総案件数 | C8: アクティブ案件 | E8: 受注数 | G8: 失注数 | I8: 成約率 | K8: 滞留案件数 | M8: 見積総額
A9: =COUNTA(案件管理!I5:I96) -> 3 | C9: =COUNTIFS(案件管理!I5:I96,"<>",案件管理!I5:I96,"<>⑥失注",案件管理!I5:I96,"<>⑦完工") -> 2 | E9: =COUNTIF(案件管理!I5:I96,"⑤受注")+COUNTIF(案件管理!I5:I96,"⑦完工") -> 2 | G9: =COUNTIF(案件管理!I5:I96,"⑥失注") -> 0 | I9: =IFERROR((COUNTIF(案件管理!I5:I96,"⑤受注")+COUNTIF(案件管理!I5:I96,"⑦完工"))/(COUNTIF(案件管理!I5:I96,"⑤受注")+COUNTIF(案件管理!I5:I96,"⑦完工")+COUNTIF(案件管理!I5:I96,"⑥失注")),0) -> 1 | K9: =COUNTIF(案件管理!L5:L96,"⚠滞留") -> 1 | M9: =SUMIF(案件管理!I5:I96,"<>",案件管理!F5:F96) -> 6554440
A10: 件 | C10: 件（進行中） | E10: 件 | G10: 件 | I10: （受注数 / 確定数） | K10: 件（30日超過） | M10: （全案件見積合計）
A11: 受注金額合計 | C11: アクティブ金額 | E11: 受注金額 | G11: 失注金額 | I11: 平均経過日数 | K11: 滞留平均日数 | M11: 金額ベース成約率
A12: =SUMIFS(案件管理!F5:F96,案件管理!I5:I96,"⑤受注")+SUMIFS(案件管理!F5:F96,案件管理!I5:I96,"⑦完工") -> 4754440 | C12: =SUMIFS(案件管理!F5:F96,案件管理!I5:I96,"<>",案件管理!I5:I96,"<>⑥失注",案件管理!I5:I96,"<>⑦完工") -> 5300000 | E12: =IFERROR(SUMIFS(案件管理!F5:F96,案件管理!I5:I96,"⑤受注")+SUMIFS(案件管理!F5:F96,案件管理!I5:I96,"⑦完工"),0) -> 4754440 | G12: =IFERROR(SUMIFS(案件管理!F5:F96,案件管理!I5:I96,"⑥失注"),0) -> 0 | I12: =IFERROR(AVERAGE(案件管理!K5:K96),0) -> 261 | K12: =IFERROR(AVERAGEIFS(案件管理!K5:K96,案件管理!L5:L96,"⚠滞留"),0) -> 385 | M12: =IFERROR((SUMIFS(案件管理!F5:F96,案件管理!I5:I96,"⑤受注")+SUMIFS(案件管理!F5:F96,案件管理!I5:I96,"⑦完工"))/SUMIF(案件管理!I5:I96,"<>",案件管理!F5:F96),0) -> 0.725377
A14: ■ ステータス別分布 | I14: ■ 担当者別実績
A15: ステータス | B15: 件数 | C15: 構成比 | D15: 見積金額合計 | E15: 平均経過日数 | F15: バーチャート | I15: 担当者 | J15: 担当案件数 | K15: 受注数 | L15: 受注率 | M15: 受注金額 | N15: 滞留数
A16: ①リード | B16: =COUNTIF(案件管理!I:I,"①リード") -> 0 | C16: =IFERROR(B16/SUM($B$16:$B$22),0) -> 0 | D16: =SUMIF(案件管理!I:I,"①リード",案件管理!F:F) -> 0 | E16: =IFERROR(AVERAGEIF(案件管理!I:I,"①リード",案件管理!K:K),"-") -> - | I16: =IF(マスター設定!J8<>"",マスター設定!J8,"") -> 吉野博 | J16: =IF(I16<>"",COUNTIF(案件管理!M:M,I16),"") -> 3 | K16: =IF(I16<>"",COUNTIFS(案件管理!M:M,I16,案件管理!I:I,"⑤受注")+COUNTIFS(案件管理!M:M,I16,案件管理!I:I,"⑦完工"),"") -> 2 | L16: =IF(AND(I16<>"",J16>0),K16/J16,"") -> 0.66666667 | M16: =IF(I16<>"",SUMIFS(案件管理!F:F,案件管理!M:M,I16,案件管理!I:I,"⑤受注")+SUMIFS(案件管理!F:F,案件管理!M:M,I16,案件管理!I:I,"⑦完工"),"") -> 4754440 | N16: =IF(I16<>"",COUNTIFS(案件管理!M:M,I16,案件管理!L:L,"⚠滞留"),"") -> 1
A17: ②商談中 | B17: =COUNTIF(案件管理!I:I,"②商談中") -> 0 | C17: =IFERROR(B17/SUM($B$16:$B$22),0) -> 0 | D17: =SUMIF(案件管理!I:I,"②商談中",案件管理!F:F) -> 0 | E17: =IFERROR(AVERAGEIF(案件管理!I:I,"②商談中",案件管理!K:K),"-") -> - | I17: =IF(マスター設定!J9<>"",マスター設定!J9,"") | J17: =IF(I17<>"",COUNTIF(案件管理!M:M,I17),"") | K17: =IF(I17<>"",COUNTIFS(案件管理!M:M,I17,案件管理!I:I,"⑤受注")+COUNTIFS(案件管理!M:M,I17,案件管理!I:I,"⑦完工"),"") | L17: =IF(AND(I17<>"",J17>0),K17/J17,"") | M17: =IF(I17<>"",SUMIFS(案件管理!F:F,案件管理!M:M,I17,案件管理!I:I,"⑤受注")+SUMIFS(案件管理!F:F,案件管理!M:M,I17,案件管理!I:I,"⑦完工"),"") | N17: =IF(I17<>"",COUNTIFS(案件管理!M:M,I17,案件管理!L:L,"⚠滞留"),"")
A18: ③見積作成中 | B18: =COUNTIF(案件管理!I:I,"③見積作成中") -> 0 | C18: =IFERROR(B18/SUM($B$16:$B$22),0) -> 0 | D18: =SUMIF(案件管理!I:I,"③見積作成中",案件管理!F:F) -> 0 | E18: =IFERROR(AVERAGEIF(案件管理!I:I,"③見積作成中",案件管理!K:K),"-") -> - | I18: =IF(マスター設定!J10<>"",マスター設定!J10,"") | J18: =IF(I18<>"",COUNTIF(案件管理!M:M,I18),"") | K18: =IF(I18<>"",COUNTIFS(案件管理!M:M,I18,案件管理!I:I,"⑤受注")+COUNTIFS(案件管理!M:M,I18,案件管理!I:I,"⑦完工"),"") | L18: =IF(AND(I18<>"",J18>0),K18/J18,"") | M18: =IF(I18<>"",SUMIFS(案件管理!F:F,案件管理!M:M,I18,案件管理!I:I,"⑤受注")+SUMIFS(案件管理!F:F,案件管理!M:M,I18,案件管理!I:I,"⑦完工"),"") | N18: =IF(I18<>"",COUNTIFS(案件管理!M:M,I18,案件管理!L:L,"⚠滞留"),"")
A19: ④見積提出済 | B19: =COUNTIF(案件管理!I:I,"④見積提出済") -> 1 | C19: =IFERROR(B19/SUM($B$16:$B$22),0) -> 0.33333333 | D19: =SUMIF(案件管理!I:I,"④見積提出済",案件管理!F:F) -> 1800000 | E19: =IFERROR(AVERAGEIF(案件管理!I:I,"④見積提出済",案件管理!K:K),"-") -> 385 | I19: =IF(マスター設定!J11<>"",マスター設定!J11,"") | J19: =IF(I19<>"",COUNTIF(案件管理!M:M,I19),"") | K19: =IF(I19<>"",COUNTIFS(案件管理!M:M,I19,案件管理!I:I,"⑤受注")+COUNTIFS(案件管理!M:M,I19,案件管理!I:I,"⑦完工"),"") | L19: =IF(AND(I19<>"",J19>0),K19/J19,"") | M19: =IF(I19<>"",SUMIFS(案件管理!F:F,案件管理!M:M,I19,案件管理!I:I,"⑤受注")+SUMIFS(案件管理!F:F,案件管理!M:M,I19,案件管理!I:I,"⑦完工"),"") | N19: =IF(I19<>"",COUNTIFS(案件管理!M:M,I19,案件管理!L:L,"⚠滞留"),"")
A20: ⑤受注 | B20: =COUNTIF(案件管理!I:I,"⑤受注") -> 1 | C20: =IFERROR(B20/SUM($B$16:$B$22),0) -> 0.33333333 | D20: =SUMIF(案件管理!I:I,"⑤受注",案件管理!F:F) -> 3500000 | E20: =IFERROR(AVERAGEIF(案件管理!I:I,"⑤受注",案件管理!K:K),"-") -> 398 | I20: =IF(マスター設定!J12<>"",マスター設定!J12,"") | J20: =IF(I20<>"",COUNTIF(案件管理!M:M,I20),"") | K20: =IF(I20<>"",COUNTIFS(案件管理!M:M,I20,案件管理!I:I,"⑤受注")+COUNTIFS(案件管理!M:M,I20,案件管理!I:I,"⑦完工"),"") | L20: =IF(AND(I20<>"",J20>0),K20/J20,"") | M20: =IF(I20<>"",SUMIFS(案件管理!F:F,案件管理!M:M,I20,案件管理!I:I,"⑤受注")+SUMIFS(案件管理!F:F,案件管理!M:M,I20,案件管理!I:I,"⑦完工"),"") | N20: =IF(I20<>"",COUNTIFS(案件管理!M:M,I20,案件管理!L:L,"⚠滞留"),"")
A21: ⑥失注 | B21: =COUNTIF(案件管理!I:I,"⑥失注") -> 0 | C21: =IFERROR(B21/SUM($B$16:$B$22),0) -> 0 | D21: =SUMIF(案件管理!I:I,"⑥失注",案件管理!F:F) -> 0 | E21: =IFERROR(AVERAGEIF(案件管理!I:I,"⑥失注",案件管理!K:K),"-") -> - | I21: =IF(マスター設定!J13<>"",マスター設定!J13,"") | J21: =IF(I21<>"",COUNTIF(案件管理!M:M,I21),"") | K21: =IF(I21<>"",COUNTIFS(案件管理!M:M,I21,案件管理!I:I,"⑤受注")+COUNTIFS(案件管理!M:M,I21,案件管理!I:I,"⑦完工"),"") | L21: =IF(AND(I21<>"",J21>0),K21/J21,"") | M21: =IF(I21<>"",SUMIFS(案件管理!F:F,案件管理!M:M,I21,案件管理!I:I,"⑤受注")+SUMIFS(案件管理!F:F,案件管理!M:M,I21,案件管理!I:I,"⑦完工"),"") | N21: =IF(I21<>"",COUNTIFS(案件管理!M:M,I21,案件管理!L:L,"⚠滞留"),"")
A22: ⑦完工 | B22: =COUNTIF(案件管理!I:I,"⑦完工") -> 1 | C22: =IFERROR(B22/SUM($B$16:$B$22),0) -> 0.33333333 | D22: =SUMIF(案件管理!I:I,"⑦完工",案件管理!F:F) -> 1254440 | E22: =IFERROR(AVERAGEIF(案件管理!I:I,"⑦完工",案件管理!K:K),"-") -> 0 | I22: =IF(マスター設定!J14<>"",マスター設定!J14,"") | J22: =IF(I22<>"",COUNTIF(案件管理!M:M,I22),"") | K22: =IF(I22<>"",COUNTIFS(案件管理!M:M,I22,案件管理!I:I,"⑤受注")+COUNTIFS(案件管理!M:M,I22,案件管理!I:I,"⑦完工"),"") | L22: =IF(AND(I22<>"",J22>0),K22/J22,"") | M22: =IF(I22<>"",SUMIFS(案件管理!F:F,案件管理!M:M,I22,案件管理!I:I,"⑤受注")+SUMIFS(案件管理!F:F,案件管理!M:M,I22,案件管理!I:I,"⑦完工"),"") | N22: =IF(I22<>"",COUNTIFS(案件管理!M:M,I22,案件管理!L:L,"⚠滞留"),"")
I23: =IF(マスター設定!J15<>"",マスター設定!J15,"") | J23: =IF(I23<>"",COUNTIF(案件管理!M:M,I23),"") | K23: =IF(I23<>"",COUNTIFS(案件管理!M:M,I23,案件管理!I:I,"⑤受注")+COUNTIFS(案件管理!M:M,I23,案件管理!I:I,"⑦完工"),"") | L23: =IF(AND(I23<>"",J23>0),K23/J23,"") | M23: =IF(I23<>"",SUMIFS(案件管理!F:F,案件管理!M:M,I23,案件管理!I:I,"⑤受注")+SUMIFS(案件管理!F:F,案件管理!M:M,I23,案件管理!I:I,"⑦完工"),"") | N23: =IF(I23<>"",COUNTIFS(案件管理!M:M,I23,案件管理!L:L,"⚠滞留"),"")
A24: ■ 滞留案件一覧（30日超過） | I24: =IF(マスター設定!J16<>"",マスター設定!J16,"") | J24: =IF(I24<>"",COUNTIF(案件管理!M:M,I24),"") | K24: =IF(I24<>"",COUNTIFS(案件管理!M:M,I24,案件管理!I:I,"⑤受注")+COUNTIFS(案件管理!M:M,I24,案件管理!I:I,"⑦完工"),"") | L24: =IF(AND(I24<>"",J24>0),K24/J24,"") | M24: =IF(I24<>"",SUMIFS(案件管理!F:F,案件管理!M:M,I24,案件管理!I:I,"⑤受注")+SUMIFS(案件管理!F:F,案件管理!M:M,I24,案件管理!I:I,"⑦完工"),"") | N24: =IF(I24<>"",COUNTIFS(案件管理!M:M,I24,案件管理!L:L,"⚠滞留"),"")
A25: 案件ID | B25: 顧客名 | C25: 案件名 | D25: ステータス | E25: 経過日数 | F25: 見積金額 | G25: 担当者 | H25: →詳細 | I25: =IF(マスター設定!J17<>"",マスター設定!J17,"") | J25: =IF(I25<>"",COUNTIF(案件管理!M:M,I25),"") | K25: =IF(I25<>"",COUNTIFS(案件管理!M:M,I25,案件管理!I:I,"⑤受注")+COUNTIFS(案件管理!M:M,I25,案件管理!I:I,"⑦完工"),"") | L25: =IF(AND(I25<>"",J25>0),K25/J25,"") | M25: =IF(I25<>"",SUMIFS(案件管理!F:F,案件管理!M:M,I25,案件管理!I:I,"⑤受注")+SUMIFS(案件管理!F:F,案件管理!M:M,I25,案件管理!I:I,"⑦完工"),"") | N25: =IF(I25<>"",COUNTIFS(案件管理!M:M,I25,案件管理!L:L,"⚠滞留"),"")
A26: {=IFERROR(_xlfn._xlws.FILTER(案件管理!A5:A96,(案件管理!L5:L96="⚠滞留")),"")} -> P-002 | B26: {=IFERROR(_xlfn._xlws.FILTER(案件管理!C5:C96,(案件管理!L5:L96="⚠滞留")),"")} -> 矢島不動産管理株式会社 | C26: {=IFERROR(_xlfn._xlws.FILTER(案件管理!D5:D96,(案件管理!L5:L96="⚠滞留")),"")} -> 吉野様邸 外壁塗装工事 | D26: {=IFERROR(_xlfn._xlws.FILTER(案件管理!I5:I96,(案件管理!L5:L96="⚠滞留")),"")} -> ④見積提出済 | E26: {=IFERROR(_xlfn._xlws.FILTER(案件管理!K5:K96,(案件管理!L5:L96="⚠滞留")),"")} -> 385 | F26: {=IFERROR(_xlfn._xlws.FILTER(案件管理!F5:F96,(案件管理!L5:L96="⚠滞留")),"")} -> 1800000 | G26: {=IFERROR(_xlfn._xlws.FILTER(案件管理!M5:M96,(案件管理!L5:L96="⚠滞留")),"")} -> 吉野博 | H26: =IF(A26="","",HYPERLINK("#案件管理!A1","→詳細")) -> →詳細
H27: =IF(A27="","",HYPERLINK("#案件管理!A1","→詳細"))
H28: =IF(A28="","",HYPERLINK("#案件管理!A1","→詳細")) | I28: ■ 顧客別実績（トップ10）
H29: =IF(A29="","",HYPERLINK("#案件管理!A1","→詳細")) | I29: 顧客ID | J29: 顧客名 | K29: 累計案件数 | L29: 累計受注額 | M29: ランク | N29: ステータス | O29: →詳細
H30: =IF(A30="","",HYPERLINK("#案件管理!A1","→詳細")) | I30: {=IFERROR(_xlfn.SORTBY(_xlfn._xlws.FILTER(顧客マスタ!A5:A104,顧客マスタ!L5:L104>0),_xlfn._xlws.FILTER(顧客マスタ!M5:M104,顧客マスタ!L5:L104>0),-1),"")} -> C-001 | J30: {=IFERROR(_xlfn.SORTBY(_xlfn._xlws.FILTER(顧客マスタ!C5:C104,顧客マスタ!L5:L104>0),_xlfn._xlws.FILTER(顧客マスタ!M5:M104,顧客マスタ!L5:L104>0),-1),"")} -> 矢島不動産管理株式会社 | K30: {=IFERROR(_xlfn.SORTBY(_xlfn._xlws.FILTER(顧客マスタ!L5:L104,顧客マスタ!L5:L104>0),_xlfn._xlws.FILTER(顧客マスタ!M5:M104,顧客マスタ!L5:L104>0),-1),"")} -> 3 | L30: {=IFERROR(_xlfn.SORTBY(_xlfn._xlws.FILTER(顧客マスタ!M5:M104,顧客マスタ!L5:L104>0),_xlfn._xlws.FILTER(顧客マスタ!M5:M104,顧客マスタ!L5:L104>0),-1),"")} -> 4754440 | M30: {=IFERROR(_xlfn.SORTBY(_xlfn._xlws.FILTER(顧客マスタ!O5:O104,顧客マスタ!L5:L104>0),_xlfn._xlws.FILTER(顧客マスタ!M5:M104,顧客マスタ!L5:L104>0),-1),"")} -> A | N30: {=IFERROR(_xlfn.SORTBY(_xlfn._xlws.FILTER(顧客マスタ!R5:R104,顧客マスタ!L5:L104>0),_xlfn._xlws.FILTER(顧客マスタ!M5:M104,顧客マスタ!L5:L104>0),-1),"")} -> アクティブ | O30: =IF(I30="","",HYPERLINK("#案件管理!A1","→詳細")) -> →詳細
O31: =IF(I31="","",HYPERLINK("#案件管理!A1","→詳細"))
A32: ■ 失注分析 | O32: =IF(I32="","",HYPERLINK("#案件管理!A1","→詳細"))
A33: ※ 案件管理の失注理由（R列）を集計。次回提案改善に活用してください。 | O33: =IF(I33="","",HYPERLINK("#案件管理!A1","→詳細"))
O34: =IF(I34="","",HYPERLINK("#案件管理!A1","→詳細"))
A35: 失注理由 | B35: 件数 | C35: 構成比 | D35: 失注金額合計 | E35: 平均見積金額 | F35: 直近失注日 | G35: 対策メモ | O35: =IF(I35="","",HYPERLINK("#案件管理!A1","→詳細"))
A36: 価格が合わない | B36: =COUNTIFS(案件管理!I:I,"⑥失注",案件管理!R:R,"*"&A36&"*") -> 0 | C36: =IFERROR(B36/SUM(B36:B40),0) -> 0 | D36: =SUMIFS(案件管理!F:F,案件管理!I:I,"⑥失注",案件管理!R:R,"*"&A36&"*") -> 0 | E36: =IFERROR(AVERAGEIFS(案件管理!F:F,案件管理!I:I,"⑥失注",案件管理!R:R,"*"&A36&"*"),0) -> 0 | F36: =IFERROR(_xlfn.MAXIFS(案件管理!J:J,案件管理!I:I,"⑥失注",案件管理!R:R,"*"&A36&"*"),"") -> 0 | O36: =IF(I36="","",HYPERLINK("#案件管理!A1","→詳細"))
A37: 工期が合わない | B37: =COUNTIFS(案件管理!I:I,"⑥失注",案件管理!R:R,"*"&A37&"*") -> 0 | C37: =IFERROR(B37/SUM(B36:B40),0) -> 0 | D37: =SUMIFS(案件管理!F:F,案件管理!I:I,"⑥失注",案件管理!R:R,"*"&A37&"*") -> 0 | E37: =IFERROR(AVERAGEIFS(案件管理!F:F,案件管理!I:I,"⑥失注",案件管理!R:R,"*"&A37&"*"),0) -> 0 | F37: =IFERROR(_xlfn.MAXIFS(案件管理!J:J,案件管理!I:I,"⑥失注",案件管理!R:R,"*"&A37&"*"),"") -> 0 | O37: =IF(I37="","",HYPERLINK("#案件管理!A1","→詳細"))
A38: 他社に決定 | B38: =COUNTIFS(案件管理!I:I,"⑥失注",案件管理!R:R,"*"&A38&"*") -> 0 | C38: =IFERROR(B38/SUM(B36:B40),0) -> 0 | D38: =SUMIFS(案件管理!F:F,案件管理!I:I,"⑥失注",案件管理!R:R,"*"&A38&"*") -> 0 | E38: =IFERROR(AVERAGEIFS(案件管理!F:F,案件管理!I:I,"⑥失注",案件管理!R:R,"*"&A38&"*"),0) -> 0 | F38: =IFERROR(_xlfn.MAXIFS(案件管理!J:J,案件管理!I:I,"⑥失注",案件管理!R:R,"*"&A38&"*"),"") -> 0 | O38: =IF(I38="","",HYPERLINK("#案件管理!A1","→詳細"))
A39: 対応・コミュニケーション | B39: =COUNTIFS(案件管理!I:I,"⑥失注",案件管理!R:R,"*"&A39&"*") -> 0 | C39: =IFERROR(B39/SUM(B36:B40),0) -> 0 | D39: =SUMIFS(案件管理!F:F,案件管理!I:I,"⑥失注",案件管理!R:R,"*"&A39&"*") -> 0 | E39: =IFERROR(AVERAGEIFS(案件管理!F:F,案件管理!I:I,"⑥失注",案件管理!R:R,"*"&A39&"*"),0) -> 0 | F39: =IFERROR(_xlfn.MAXIFS(案件管理!J:J,案件管理!I:I,"⑥失注",案件管理!R:R,"*"&A39&"*"),"") -> 0 | O39: =IF(I39="","",HYPERLINK("#案件管理!A1","→詳細"))
A40: その他・不明 | B40: =COUNTIFS(案件管理!I:I,"⑥失注",案件管理!R:R,"*"&A40&"*") -> 0 | C40: =IFERROR(B40/SUM(B36:B40),0) -> 0 | D40: =SUMIFS(案件管理!F:F,案件管理!I:I,"⑥失注",案件管理!R:R,"*"&A40&"*") -> 0 | E40: =IFERROR(AVERAGEIFS(案件管理!F:F,案件管理!I:I,"⑥失注",案件管理!R:R,"*"&A40&"*"),0) -> 0 | F40: =IFERROR(_xlfn.MAXIFS(案件管理!J:J,案件管理!I:I,"⑥失注",案件管理!R:R,"*"&A40&"*"),"") -> 0
A41: 合計 | B41: =SUM(B36:B40) -> 0 | C41: =IFERROR(B41/B41,0) -> 0 | D41: =SUM(D36:D40) -> 0 | E41: =IFERROR(D41/B41,0) -> 0
A43: ■ 請求・入金管理
...

Sheet 案件管理
A1: 案件管理 / プロジェクトパイプライン
A2: 株式会社LinK - CRM案件管理システム
A3: ※ 全案件の進捗・ステータスを一元管理。経過日数の自動計算で滞留案件を即座に把握できます。
A4: 案件ID | B4: 顧客ID | C4: 顧客名 | D4: 案件名 | E4: 工事内容 | F4: 見積金額 | G4: 実行予算 | H4: 粗利率 | I4: ステータス | J4: ステータス変更日 | K4: 経過日数 | L4: 滞留アラート | M4: 担当者 | N4: 受注日 | O4: 着工予定日 | P4: 完工日 | Q4: 請求予定額 | R4: 失注理由 | S4: 作成日 | T4: 備考 | U4: 完工予定日 | V4: 工期余日 | W4: 工期アラート | X4: 請求書ステータス | Y4: 請求日 | Z4: 請求金額 | AA4: 入金ステータス | AB4: 入金日 | AC4: 入金額 | AD4: 受注区分 | AE4: 施工住所 | AF4: 物件名
A5: P-001 | B5: C-001 | C5: =IFERROR(VLOOKUP(B5,顧客マスタ!A:C,3,FALSE),"") -> 矢島不動産管理株式会社 | D5: 吉野様邸 リフォーム工事 | E5: 内装・電気・給排水 | F5: 3500000 | G5: 2800000 | H5: =IF(AND(F5<>"",G5<>""),(F5-G5)/F5,"") -> 0.2 | I5: ⑤受注 | J5: 45672 | K5: =IF(J5<>"",TODAY()-J5,"") -> 398 | L5: =IF(AND(K5<>"",K5>30,NOT(OR(I5="⑤受注",I5="⑦完工",I5="⑥失注"))),"⚠滞留","") | M5: 吉野博 | N5: 45677 | O5: 45689 | P5: 45731 | Q5: 3500000 | S5: 45662 | T5: 受注済み・工事完了 | U5: 45731 | V5: =IF(AND(U5<>"",OR(I5="⑤受注",I5="③見積作成中",I5="④見積提出済")),U5-TODAY(),"") -> -339 | W5: =IF(V5="","",IF(V5<0,"⚠工期超過",IF(V5<=7,"⚠残り"&V5&"日",""))) -> ⚠工期超過 | X5: =IF(I5="","",IF(COUNTIFS(請求管理!B:B,A5)>0,"✅発行済","❌未発行")) -> ✅発行済 | Y5: =IF(I5="","",IFERROR(IF(COUNTIFS(請求管理!B:B,A5)=0,"",_xlfn.MAXIFS(請求管理!F:F,請求管理!B:B,A5)),"")) -> 45735 | Z5: =IF(I5="","",IFERROR(IF(COUNTIFS(請求管理!B:B,A5)=0,"",SUMIFS(請求管理!G:G,請求管理!B:B,A5)),"")) -> 3500000 | AA5: =IF(I5="","",IF(COUNTIFS(請求管理!B:B,A5)=0,"",IF(SUMIFS(請求管理!J:J,請求管理!B:B,A5)<=0,"✅入金済","❌未入金"))) -> ✅入金済 | AB5: =IF(I5="","",IFERROR(IF(COUNTIFS(請求管理!B:B,A5)=0,"",_xlfn.MAXIFS(請求管理!H:H,請求管理!B:B,A5)),"")) -> 45760 | AC5: =IF(I5="","",IFERROR(IF(COUNTIFS(請求管理!B:B,A5)=0,"",SUMIFS(請求管理!I:I,請求管理!B:B,A5)),"")) -> 3500000 | AD5: =IF(OR(I5="⑤受注",I5="⑦完工"),"🟢受注",IF(I5="⑥失注","🔴失注",IF(I5="","","🟡商談中"))) -> 🟢受注
A6: P-002 | B6: C-001 | C6: =IFERROR(VLOOKUP(B6,顧客マスタ!A:C,3,FALSE),"") -> 矢島不動産管理株式会社 | D6: 吉野様邸 外壁塗装工事 | E6: 外壁・屋根塗装 | F6: 1800000 | H6: =IF(AND(F6<>"",G6<>""),(F6-G6)/F6,"") | I6: ④見積提出済 | J6: 45685 | K6: =IF(J6<>"",TODAY()-J6,"") -> 385 | L6: =IF(AND(K6<>"",K6>30,NOT(OR(I6="⑤受注",I6="⑦完工",I6="⑥失注"))),"⚠滞留","") -> ⚠滞留 | M6: 吉野博 | S6: 45677 | T6: 見積提出済・返事待ち | V6: =IF(AND(U6<>"",OR(I6="⑤受注",I6="③見積作成中",I6="④見積提出済")),U6-TODAY(),"") | W6: =IF(V6="","",IF(V6<0,"⚠工期超過",IF(V6<=7,"⚠残り"&V6&"日",""))) | X6: =IF(I6="","",IF(COUNTIFS(請求管理!B:B,A6)>0,"✅発行済","❌未発行")) -> ❌未発行 | Y6: =IF(I6="","",IFERROR(IF(COUNTIFS(請求管理!B:B,A6)=0,"",_xlfn.MAXIFS(請求管理!F:F,請求管理!B:B,A6)),"")) | Z6: =IF(I6="","",IFERROR(IF(COUNTIFS(請求管理!B:B,A6)=0,"",SUMIFS(請求管理!G:G,請求管理!B:B,A6)),"")) | AA6: =IF(I6="","",IF(COUNTIFS(請求管理!B:B,A6)=0,"",IF(SUMIFS(請求管理!J:J,請求管理!B:B,A6)<=0,"✅入金済","❌未入金"))) | AB6: =IF(I6="","",IFERROR(IF(COUNTIFS(請求管理!B:B,A6)=0,"",_xlfn.MAXIFS(請求管理!H:H,請求管理!B:B,A6)),"")) | AC6: =IF(I6="","",IFERROR(IF(COUNTIFS(請求管理!B:B,A6)=0,"",SUMIFS(請求管理!I:I,請求管理!B:B,A6)),"")) | AD6: =IF(OR(I6="⑤受注",I6="⑦完工"),"🟢受注",IF(I6="⑥失注","🔴失注",IF(I6="","","🟡商談中"))) -> 🟡商談中
A7: P-003 | B7: C-001 | C7: =IFERROR(VLOOKUP(B7,顧客マスタ!A:C,3,FALSE),"") -> 矢島不動産管理株式会社 | D7: 吉野様邸 キッチンリフォーム | E7: キッチン設備・内装 | F7: ='P-003_吉野様邸キッチン'!K50 -> 1254440 | G7: ='P-003_吉野様邸キッチン'!G50 -> 829180 | H7: =IF(AND(F7<>"",G7<>""),(F7-G7)/F7,"") -> 0.33900386 | I7: ⑦完工 | J7: =TODAY() -> 46070 | K7: =IF(J7<>"",TODAY()-J7,"") -> 0 | L7: =IF(AND(K7<>"",K7>30,NOT(OR(I7="⑤受注",I7="⑦完工",I7="⑥失注"))),"⚠滞留","") | M7: 吉野博 | P7: =TODAY() -> 46070 | Q7: =F7 -> 1254440 | S7: =TODAY() -> 46070 | T7: ⑦完工 - 工事項目DB蓄積済み | V7: =IF(AND(U7<>"",OR(I7="⑤受注",I7="③見積作成中",I7="④見積提出済")),U7-TODAY(),"") | W7: =IF(V7="","",IF(V7<0,"⚠工期超過",IF(V7<=7,"⚠残り"&V7&"日",""))) | X7: =IF(I7="","",IF(COUNTIFS(請求管理!B:B,A7)>0,"✅発行済","❌未発行")) -> ✅発行済 | Y7: =IF(I7="","",IFERROR(IF(COUNTIFS(請求管理!B:B,A7)=0,"",_xlfn.MAXIFS(請求管理!F:F,請求管理!B:B,A7)),"")) -> 46064 | Z7: =IF(I7="","",IFERROR(IF(COUNTIFS(請求管理!B:B,A7)=0,"",SUMIFS(請求管理!G:G,請求管理!B:B,A7)),"")) -> 1254440 | AA7: =IF(I7="","",IF(COUNTIFS(請求管理!B:B,A7)=0,"",IF(SUMIFS(請求管理!J:J,請求管理!B:B,A7)<=0,"✅入金済","❌未入金"))) -> ❌未入金 | AB7: =IF(I7="","",IFERROR(IF(COUNTIFS(請求管理!B:B,A7)=0,"",_xlfn.MAXIFS(請求管理!H:H,請求管理!B:B,A7)),"")) -> 46040 | AC7: =IF(I7="","",IFERROR(IF(COUNTIFS(請求管理!B:B,A7)=0,"",SUMIFS(請求管理!I:I,請求管理!B:B,A7)),"")) -> 627220 | AD7: =IF(OR(I7="⑤受注",I7="⑦完工"),"🟢受注",IF(I7="⑥失注","🔴失注",IF(I7="","","🟡商談中"))) -> 🟢受注
A8: P-012 | C8: =IFERROR(VLOOKUP(B8,顧客マスタ!A:C,3,FALSE),"") | H8: =IF(AND(F8<>"",G8<>""),(F8-G8)/F8,"") | K8: =IF(J8<>"",TODAY()-J8,"") | L8: =IF(AND(K8<>"",K8>30,NOT(OR(I8="⑤受注",I8="⑦完工",I8="⑥失注"))),"⚠滞留","") | V8: =IF(AND(U8<>"",OR(I8="⑤受注",I8="③見積作成中",I8="④見積提出済")),U8-TODAY(),"") | W8: =IF(V8="","",IF(V8<0,"⚠工期超過",IF(V8<=7,"⚠残り"&V8&"日",""))) | X8: =IF(I8="","",IF(COUNTIFS(請求管理!B:B,A8)>0,"✅発行済","❌未発行")) | Y8: =IF(I8="","",IFERROR(IF(COUNTIFS(請求管理!B:B,A8)=0,"",_xlfn.MAXIFS(請求管理!F:F,請求管理!B:B,A8)),"")) | Z8: =IF(I8="","",IFERROR(IF(COUNTIFS(請求管理!B:B,A8)=0,"",SUMIFS(請求管理!G:G,請求管理!B:B,A8)),"")) | AA8: =IF(I8="","",IF(COUNTIFS(請求管理!B:B,A8)=0,"",IF(SUMIFS(請求管理!J:J,請求管理!B:B,A8)<=0,"✅入金済","❌未入金"))) | AB8: =IF(I8="","",IFERROR(IF(COUNTIFS(請求管理!B:B,A8)=0,"",_xlfn.MAXIFS(請求管理!H:H,請求管理!B:B,A8)),"")) | AC8: =IF(I8="","",IFERROR(IF(COUNTIFS(請求管理!B:B,A8)=0,"",SUMIFS(請求管理!I:I,請求管理!B:B,A8)),"")) | AD8: =IF(OR(I8="⑤受注",I8="⑦完工"),"🟢受注",IF(I8="⑥失注","🔴失注",IF(I8="","","🟡商談中")))
A9: P-013 | C9: =IFERROR(VLOOKUP(B9,顧客マスタ!A:C,3,FALSE),"") | H9: =IF(AND(F9<>"",G9<>""),(F9-G9)/F9,"") | K9: =IF(J9<>"",TODAY()-J9,"") | L9: =IF(AND(K9<>"",K9>30,NOT(OR(I9="⑤受注",I9="⑦完工",I9="⑥失注"))),"⚠滞留","") | V9: =IF(AND(U9<>"",OR(I9="⑤受注",I9="③見積作成中",I9="④見積提出済")),U9-TODAY(),"") | W9: =IF(V9="","",IF(V9<0,"⚠工期超過",IF(V9<=7,"⚠残り"&V9&"日",""))) | X9: =IF(I9="","",IF(COUNTIFS(請求管理!B:B,A9)>0,"✅発行済","❌未発行")) | Y9: =IF(I9="","",IFERROR(IF(COUNTIFS(請求管理!B:B,A9)=0,"",_xlfn.MAXIFS(請求管理!F:F,請求管理!B:B,A9)),"")) | Z9: =IF(I9="","",IFERROR(IF(COUNTIFS(請求管理!B:B,A9)=0,"",SUMIFS(請求管理!G:G,請求管理!B:B,A9)),"")) | AA9: =IF(I9="","",IF(COUNTIFS(請求管理!B:B,A9)=0,"",IF(SUMIFS(請求管理!J:J,請求管理!B:B,A9)<=0,"✅入金済","❌未入金"))) | AB9: =IF(I9="","",IFERROR(IF(COUNTIFS(請求管理!B:B,A9)=0,"",_xlfn.MAXIFS(請求管理!H:H,請求管理!B:B,A9)),"")) | AC9: =IF(I9="","",IFERROR(IF(COUNTIFS(請求管理!B:B,A9)=0,"",SUMIFS(請求管理!I:I,請求管理!B:B,A9)),"")) | AD9: =IF(OR(I9="⑤受注",I9="⑦完工"),"🟢受注",IF(I9="⑥失注","🔴失注",IF(I9="","","🟡商談中")))
A10: P-014 | C10: =IFERROR(VLOOKUP(B10,顧客マスタ!A:C,3,FALSE),"") | H10: =IF(AND(F10<>"",G10<>""),(F10-G10)/F10,"") | K10: =IF(J10<>"",TODAY()-J10,"") | L10: =IF(AND(K10<>"",K10>30,NOT(OR(I10="⑤受注",I10="⑦完工",I10="⑥失注"))),"⚠滞留","") | V10: =IF(AND(U10<>"",OR(I10="⑤受注",I10="③見積作成中",I10="④見積提出済")),U10-TODAY(),"") | W10: =IF(V10="","",IF(V10<0,"⚠工期超過",IF(V10<=7,"⚠残り"&V10&"日",""))) | X10: =IF(I10="","",IF(COUNTIFS(請求管理!B:B,A10)>0,"✅発行済","❌未発行")) | Y10: =IF(I10="","",IFERROR(IF(COUNTIFS(請求管理!B:B,A10)=0,"",_xlfn.MAXIFS(請求管理!F:F,請求管理!B:B,A10)),"")) | Z10: =IF(I10="","",IFERROR(IF(COUNTIFS(請求管理!B:B,A10)=0,"",SUMIFS(請求管理!G:G,請求管理!B:B,A10)),"")) | AA10: =IF(I10="","",IF(COUNTIFS(請求管理!B:B,A10)=0,"",IF(SUMIFS(請求管理!J:J,請求管理!B:B,A10)<=0,"✅入金済","❌未入金"))) | AB10: =IF(I10="","",IFERROR(IF(COUNTIFS(請求管理!B:B,A10)=0,"",_xlfn.MAXIFS(請求管理!H:H,請求管理!B:B,A10)),"")) | AC10: =IF(I10="","",IFERROR(IF(COUNTIFS(請求管理!B:B,A10)=0,"",SUMIFS(請求管理!I:I,請求管理!B:B,A10)),"")) | AD10: =IF(OR(I10="⑤受注",I10="⑦完工"),"🟢受注",IF(I10="⑥失注","🔴失注",IF(I10="","","🟡商談中")))
A11: P-015 | C11: =IFERROR(VLOOKUP(B11,顧客マスタ!A:C,3,FALSE),"") | H11: =IF(AND(F11<>"",G11<>""),(F11-G11)/F11,"") | K11: =IF(J11<>"",TODAY()-J11,"") | L11: =IF(AND(K11<>"",K11>30,NOT(OR(I11="⑤受注",I11="⑦完工",I11="⑥失注"))),"⚠滞留","") | V11: =IF(AND(U11<>"",OR(I11="⑤受注",I11="③見積作成中",I11="④見積提出済")),U11-TODAY(),"") | W11: =IF(V11="","",IF(V11<0,"⚠工期超過",IF(V11<=7,"⚠残り"&V11&"日",""))) | X11: =IF(I11="","",IF(COUNTIFS(請求管理!B:B,A11)>0,"✅発行済","❌未発行")) | Y11: =IF(I11="","",IFERROR(IF(COUNTIFS(請求管理!B:B,A11)=0,"",_xlfn.MAXIFS(請求管理!F:F,請求管理!B:B,A11)),"")) | Z11: =IF(I11="","",IFERROR(IF(COUNTIFS(請求管理!B:B,A11)=0,"",SUMIFS(請求管理!G:G,請求管理!B:B,A11)),"")) | AA11: =IF(I11="","",IF(COUNTIFS(請求管理!B:B,A11)=0,"",IF(SUMIFS(請求管理!J:J,請求管理!B:B,A11)<=0,"✅入金済","❌未入金"))) | AB11: =IF(I11="","",IFERROR(IF(COUNTIFS(請求管理!B:B,A11)=0,"",_xlfn.MAXIFS(請求管理!H:H,請求管理!B:B,A11)),"")) | AC11: =IF(I11="","",IFERROR(IF(COUNTIFS(請求管理!B:B,A11)=0,"",SUMIFS(請求管理!I:I,請求管理!B:B,A11)),"")) | AD11: =IF(OR(I11="⑤受注",I11="⑦完工"),"🟢受注",IF(I11="⑥失注","🔴失注",IF(I11="","","🟡商談中")))
A12: P-016 | C12: =IFERROR(VLOOKUP(B12,顧客マスタ!A:C,3,FALSE),"") | H12: =IF(AND(F12<>"",G12<>""),(F12-G12)/F12,"") | K12: =IF(J12<>"",TODAY()-J12,"") | L12: =IF(AND(K12<>"",K12>30,NOT(OR(I12="⑤受注",I12="⑦完工",I12="⑥失注"))),"⚠滞留","") | V12: =IF(AND(U12<>"",OR(I12="⑤受注",I12="③見積作成中",I12="④見積提出済")),U12-TODAY(),"") | W12: =IF(V12="","",IF(V12<0,"⚠工期超過",IF(V12<=7,"⚠残り"&V12&"日",""))) | X12: =IF(I12="","",IF(COUNTIFS(請求管理!B:B,A12)>0,"✅発行済","❌未発行")) | Y12: =IF(I12="","",IFERROR(IF(COUNTIFS(請求管理!B:B,A12)=0,"",_xlfn.MAXIFS(請求管理!F:F,請求管理!B:B,A12)),"")) | Z12: =IF(I12="","",IFERROR(IF(COUNTIFS(請求管理!B:B,A12)=0,"",SUMIFS(請求管理!G:G,請求管理!B:B,A12)),"")) | AA12: =IF(I12="","",IF(COUNTIFS(請求管理!B:B,A12)=0,"",IF(SUMIFS(請求管理!J:J,請求管理!B:B,A12)<=0,"✅入金済","❌未入金"))) | AB12: =IF(I12="","",IFERROR(IF(COUNTIFS(請求管理!B:B,A12)=0,"",_xlfn.MAXIFS(請求管理!H:H,請求管理!B:B,A12)),"")) | AC12: =IF(I12="","",IFERROR(IF(COUNTIFS(請求管理!B:B,A12)=0,"",SUMIFS(請求管理!I:I,請求管理!B:B,A12)),"")) | AD12: =IF(OR(I12="⑤受注",I12="⑦完工"),"🟢受注",IF(I12="⑥失注","🔴失注",IF(I12="","","🟡商談中")))
A13: P-017 | C13: =IFERROR(VLOOKUP(B13,顧客マスタ!A:C,3,FALSE),"") | H13: =IF(AND(F13<>"",G13<>""),(F13-G13)/F13,"") | K13: =IF(J13<>"",TODAY()-J13,"") | L13: =IF(AND(K13<>"",K13>30,NOT(OR(I13="⑤受注",I13="⑦完工",I13="⑥失注"))),"⚠滞留","") | V13: =IF(AND(U13<>"",OR(I13="⑤受注",I13="③見積作成中",I13="④見積提出済")),U13-TODAY(),"") | W13: =IF(V13="","",IF(V13<0,"⚠工期超過",IF(V13<=7,"⚠残り"&V13&"日",""))) | X13: =IF(I13="","",IF(COUNTIFS(請求管理!B:B,A13)>0,"✅発行済","❌未発行")) | Y13: =IF(I13="","",IFERROR(IF(COUNTIFS(請求管理!B:B,A13)=0,"",_xlfn.MAXIFS(請求管理!F:F,請求管理!B:B,A13)),"")) | Z13: =IF(I13="","",IFERROR(IF(COUNTIFS(請求管理!B:B,A13)=0,"",SUMIFS(請求管理!G:G,請求管理!B:B,A13)),"")) | AA13: =IF(I13="","",IF(COUNTIFS(請求管理!B:B,A13)=0,"",IF(SUMIFS(請求管理!J:J,請求管理!B:B,A13)<=0,"✅入金済","❌未入金"))) | AB13: =IF(I13="","",IFERROR(IF(COUNTIFS(請求管理!B:B,A13)=0,"",_xlfn.MAXIFS(請求管理!H:H,請求管理!B:B,A13)),"")) | AC13: =IF(I13="","",IFERROR(IF(COUNTIFS(請求管理!B:B,A13)=0,"",SUMIFS(請求管理!I:I,請求管理!B:B,A13)),"")) | AD13: =IF(OR(I13="⑤受注",I13="⑦完工"),"🟢受注",IF(I13="⑥失注","🔴失注",IF(I13="","","🟡商談中")))
A14: P-018 | C14: =IFERROR(VLOOKUP(B14,顧客マスタ!A:C,3,FALSE),"") | H14: =IF(AND(F14<>"",G14<>""),(F14-G14)/F14,"") | K14: =IF(J14<>"",TODAY()-J14,"") | L14: =IF(AND(K14<>"",K14>30,NOT(OR(I14="⑤受注",I14="⑦完工",I14="⑥失注"))),"⚠滞留","") | V14: =IF(AND(U14<>"",OR(I14="⑤受注",I14="③見積作成中",I14="④見積提出済")),U14-TODAY(),"") | W14: =IF(V14="","",IF(V14<0,"⚠工期超過",IF(V14<=7,"⚠残り"&V14&"日",""))) | X14: =IF(I14="","",IF(COUNTIFS(請求管理!B:B,A14)>0,"✅発行済","❌未発行")) | Y14: =IF(I14="","",IFERROR(IF(COUNTIFS(請求管理!B:B,A14)=0,"",_xlfn.MAXIFS(請求管理!F:F,請求管理!B:B,A14)),"")) | Z14: =IF(I14="","",IFERROR(IF(COUNTIFS(請求管理!B:B,A14)=0,"",SUMIFS(請求管理!G:G,請求管理!B:B,A14)),"")) | AA14: =IF(I14="","",IF(COUNTIFS(請求管理!B:B,A14)=0,"",IF(SUMIFS(請求管理!J:J,請求管理!B:B,A14)<=0,"✅入金済","❌未入金"))) | AB14: =IF(I14="","",IFERROR(IF(COUNTIFS(請求管理!B:B,A14)=0,"",_xlfn.MAXIFS(請求管理!H:H,請求管理!B:B,A14)),"")) | AC14: =IF(I14="","",IFERROR(IF(COUNTIFS(請求管理!B:B,A14)=0,"",SUMIFS(請求管理!I:I,請求管理!B:B,A14)),"")) | AD14: =IF(OR(I14="⑤受注",I14="⑦完工"),"🟢受注",IF(I14="⑥失注","🔴失注",IF(I14="","","🟡商談中")))
A15: P-019 | C15: =IFERROR(VLOOKUP(B15,顧客マスタ!A:C,3,FALSE),"") | H15: =IF(AND(F15<>"",G15<>""),(F15-G15)/F15,"") | K15: =IF(J15<>"",TODAY()-J15,"") | L15: =IF(AND(K15<>"",K15>30,NOT(OR(I15="⑤受注",I15="⑦完工",I15="⑥失注"))),"⚠滞留","") | V15: =IF(AND(U15<>"",OR(I15="⑤受注",I15="③見積作成中",I15="④見積提出済")),U15-TODAY(),"") | W15: =IF(V15="","",IF(V15<0,"⚠工期超過",IF(V15<=7,"⚠残り"&V15&"日",""))) | X15: =IF(I15="","",IF(COUNTIFS(請求管理!B:B,A15)>0,"✅発行済","❌未発行")) | Y15: =IF(I15="","",IFERROR(IF(COUNTIFS(請求管理!B:B,A15)=0,"",_xlfn.MAXIFS(請求管理!F:F,請求管理!B:B,A15)),"")) | Z15: =IF(I15="","",IFERROR(IF(COUNTIFS(請求管理!B:B,A15)=0,"",SUMIFS(請求管理!G:G,請求管理!B:B,A15)),"")) | AA15: =IF(I15="","",IF(COUNTIFS(請求管理!B:B,A15)=0,"",IF(SUMIFS(請求管理!J:J,請求管理!B:B,A15)<=0,"✅入金済","❌未入金"))) | AB15: =IF(I15="","",IFERROR(IF(COUNTIFS(請求管理!B:B,A15)=0,"",_xlfn.MAXIFS(請求管理!H:H,請求管理!B:B,A15)),"")) | AC15: =IF(I15="","",IFERROR(IF(COUNTIFS(請求管理!B:B,A15)=0,"",SUMIFS(請求管理!I:I,請求管理!B:B,A15)),"")) | AD15: =IF(OR(I15="⑤受注",I15="⑦完工"),"🟢受注",IF(I15="⑥失注","🔴失注",IF(I15="","","🟡商談中")))
A16: P-020 | C16: =IFERROR(VLOOKUP(B16,顧客マスタ!A:C,3,FALSE),"") | H16: =IF(AND(F16<>"",G16<>""),(F16-G16)/F16,"") | K16: =IF(J16<>"",TODAY()-J16,"") | L16: =IF(AND(K16<>"",K16>30,NOT(OR(I16="⑤受注",I16="⑦完工",I16="⑥失注"))),"⚠滞留","") | V16: =IF(AND(U16<>"",OR(I16="⑤受注",I16="③見積作成中",I16="④見積提出済")),U16-TODAY(),"") | W16: =IF(V16="","",IF(V16<0,"⚠工期超過",IF(V16<=7,"⚠残り"&V16&"日",""))) | X16: =IF(I16="","",IF(COUNTIFS(請求管理!B:B,A16)>0,"✅発行済","❌未発行")) | Y16: =IF(I16="","",IFERROR(IF(COUNTIFS(請求管理!B:B,A16)=0,"",_xlfn.MAXIFS(請求管理!F:F,請求管理!B:B,A16)),"")) | Z16: =IF(I16="","",IFERROR(IF(COUNTIFS(請求管理!B:B,A16)=0,"",SUMIFS(請求管理!G:G,請求管理!B:B,A16)),"")) | AA16: =IF(I16="","",IF(COUNTIFS(請求管理!B:B,A16)=0,"",IF(SUMIFS(請求管理!J:J,請求管理!B:B,A16)<=0,"✅入金済","❌未入金"))) | AB16: =IF(I16="","",IFERROR(IF(COUNTIFS(請求管理!B:B,A16)=0,"",_xlfn.MAXIFS(請求管理!H:H,請求管理!B:B,A16)),"")) | AC16: =IF(I16="","",IFERROR(IF(COUNTIFS(請求管理!B:B,A16)=0,"",SUMIFS(請求管理!I:I,請求管理!B:B,A16)),"")) | AD16: =IF(OR(I16="⑤受注",I16="⑦完工"),"🟢受注",IF(I16="⑥失注","🔴失注",IF(I16="","","🟡商談中")))
C17: =IFERROR(VLOOKUP(B17,顧客マスタ!A:C,3,FALSE),"") | H17: =IF(AND(F17<>"",G17<>""),(F17-G17)/F17,"") | K17: =IF(J17<>"",TODAY()-J17,"") | L17: =IF(AND(K17<>"",K17>30,NOT(OR(I17="⑤受注",I17="⑦完工",I17="⑥失注"))),"⚠滞留","") | V17: =IF(AND(U17<>"",OR(I17="⑤受注",I17="③見積作成中",I17="④見積提出済")),U17-TODAY(),"") | W17: =IF(V17="","",IF(V17<0,"⚠工期超過",IF(V17<=7,"⚠残り"&V17&"日",""))) | X17: =IF(I17="","",IF(COUNTIFS(請求管理!B:B,A17)>0,"✅発行済","❌未発行")) | Y17: =IF(I17="","",IFERROR(IF(COUNTIFS(請求管理!B:B,A17)=0,"",_xlfn.MAXIFS(請求管理!F:F,請求管理!B:B,A17)),"")) | Z17: =IF(I17="","",IFERROR(IF(COUNTIFS(請求管理!B:B,A17)=0,"",SUMIFS(請求管理!G:G,請求管理!B:B,A17)),"")) | AA17: =IF(I17="","",IF(COUNTIFS(請求管理!B:B,A17)=0,"",IF(SUMIFS(請求管理!J:J,請求管理!B:B,A17)<=0,"✅入金済","❌未入金"))) | AB17: =IF(I17="","",IFERROR(IF(COUNTIFS(請求管理!B:B,A17)=0,"",_xlfn.MAXIFS(請求管理!H:H,請求管理!B:B,A17)),"")) | AC17: =IF(I17="","",IFERROR(IF(COUNTIFS(請求管理!B:B,A17)=0,"",SUMIFS(請求管理!I:I,請求管理!B:B,A17)),"")) | AD17: =IF(OR(I17="⑤受注",I17="⑦完工"),"🟢受注",IF(I17="⑥失注","🔴失注",IF(I17="","","🟡商談中")))
C18: =IFERROR(VLOOKUP(B18,顧客マスタ!A:C,3,FALSE),"") | H18: =IF(AND(F18<>"",G18<>""),(F18-G18)/F18,"") | K18: =IF(J18<>"",TODAY()-J18,"") | L18: =IF(AND(K18<>"",K18>30,NOT(OR(I18="⑤受注",I18="⑦完工",I18="⑥失注"))),"⚠滞留","") | V18: =IF(AND(U18<>"",OR(I18="⑤受注",I18="③見積作成中",I18="④見積提出済")),U18-TODAY(),"") | W18: =IF(V18="","",IF(V18<0,"⚠工期超過",IF(V18<=7,"⚠残り"&V18&"日",""))) | X18: =IF(I18="","",IF(COUNTIFS(請求管理!B:B,A18)>0,"✅発行済","❌未発行")) | Y18: =IF(I18="","",IFERROR(IF(COUNTIFS(請求管理!B:B,A18)=0,"",_xlfn.MAXIFS(請求管理!F:F,請求管理!B:B,A18)),"")) | Z18: =IF(I18="","",IFERROR(IF(COUNTIFS(請求管理!B:B,A18)=0,"",SUMIFS(請求管理!G:G,請求管理!B:B,A18)),"")) | AA18: =IF(I18="","",IF(COUNTIFS(請求管理!B:B,A18)=0,"",IF(SUMIFS(請求管理!J:J,請求管理!B:B,A18)<=0,"✅入金済","❌未入金"))) | AB18: =IF(I18="","",IFERROR(IF(COUNTIFS(請求管理!B:B,A18)=0,"",_xlfn.MAXIFS(請求管理!H:H,請求管理!B:B,A18)),"")) | AC18: =IF(I18="","",IFERROR(IF(COUNTIFS(請求管理!B:B,A18)=0,"",SUMIFS(請求管理!I:I,請求管理!B:B,A18)),"")) | AD18: =IF(OR(I18="⑤受注",I18="⑦完工"),"🟢受注",IF(I18="⑥失注","🔴失注",IF(I18="","","🟡商談中")))
C19: =IFERROR(VLOOKUP(B19,顧客マスタ!A:C,3,FALSE),"") | H19: =IF(AND(F19<>"",G19<>""),(F19-G19)/F19,"") | K19: =IF(J19<>"",TODAY()-J19,"") | L19: =IF(AND(K19<>"",K19>30,NOT(OR(I19="⑤受注",I19="⑦完工",I19="⑥失注"))),"⚠滞留","") | V19: =IF(AND(U19<>"",OR(I19="⑤受注",I19="③見積作成中",I19="④見積提出済")),U19-TODAY(),"") | W19: =IF(V19="","",IF(V19<0,"⚠工期超過",IF(V19<=7,"⚠残り"&V19&"日",""))) | X19: =IF(I19="","",IF(COUNTIFS(請求管理!B:B,A19)>0,"✅発行済","❌未発行")) | Y19: =IF(I19="","",IFERROR(IF(COUNTIFS(請求管理!B:B,A19)=0,"",_xlfn.MAXIFS(請求管理!F:F,請求管理!B:B,A19)),"")) | Z19: =IF(I19="","",IFERROR(IF(COUNTIFS(請求管理!B:B,A19)=0,"",SUMIFS(請求管理!G:G,請求管理!B:B,A19)),"")) | AA19: =IF(I19="","",IF(COUNTIFS(請求管理!B:B,A19)=0,"",IF(SUMIFS(請求管理!J:J,請求管理!B:B,A19)<=0,"✅入金済","❌未入金"))) | AB19: =IF(I19="","",IFERROR(IF(COUNTIFS(請求管理!B:B,A19)=0,"",_xlfn.MAXIFS(請求管理!H:H,請求管理!B:B,A19)),"")) | AC19: =IF(I19="","",IFERROR(IF(COUNTIFS(請求管理!B:B,A19)=0,"",SUMIFS(請求管理!I:I,請求管理!B:B,A19)),"")) | AD19: =IF(OR(I19="⑤受注",I19="⑦完工"),"🟢受注",IF(I19="⑥失注","🔴失注",IF(I19="","","🟡商談中")))
C20: =IFERROR(VLOOKUP(B20,顧客マスタ!A:C,3,FALSE),"") | H20: =IF(AND(F20<>"",G20<>""),(F20-G20)/F20,"") | K20: =IF(J20<>"",TODAY()-J20,"") | L20: =IF(AND(K20<>"",K20>30,NOT(OR(I20="⑤受注",I20="⑦完工",I20="⑥失注"))),"⚠滞留","") | V20: =IF(AND(U20<>"",OR(I20="⑤受注",I20="③見積作成中",I20="④見積提出済")),U20-TODAY(),"") | W20: =IF(V20="","",IF(V20<0,"⚠工期超過",IF(V20<=7,"⚠残り"&V20&"日",""))) | X20: =IF(I20="","",IF(COUNTIFS(請求管理!B:B,A20)>0,"✅発行済","❌未発行")) | Y20: =IF(I20="","",IFERROR(IF(COUNTIFS(請求管理!B:B,A20)=0,"",_xlfn.MAXIFS(請求管理!F:F,請求管理!B:B,A20)),"")) | Z20: =IF(I20="","",IFERROR(IF(COUNTIFS(請求管理!B:B,A20)=0,"",SUMIFS(請求管理!G:G,請求管理!B:B,A20)),"")) | AA20: =IF(I20="","",IF(COUNTIFS(請求管理!B:B,A20)=0,"",IF(SUMIFS(請求管理!J:J,請求管理!B:B,A20)<=0,"✅入金済","❌未入金"))) | AB20: =IF(I20="","",IFERROR(IF(COUNTIFS(請求管理!B:B,A20)=0,"",_xlfn.MAXIFS(請求管理!H:H,請求管理!B:B,A20)),"")) | AC20: =IF(I20="","",IFERROR(IF(COUNTIFS(請求管理!B:B,A20)=0,"",SUMIFS(請求管理!I:I,請求管理!B:B,A20)),"")) | AD20: =IF(OR(I20="⑤受注",I20="⑦完工"),"🟢受注",IF(I20="⑥失注","🔴失注",IF(I20="","","🟡商談中")))
C21: =IFERROR(VLOOKUP(B21,顧客マスタ!A:C,3,FALSE),"") | H21: =IF(AND(F21<>"",G21<>""),(F21-G21)/F21,"") | K21: =IF(J21<>"",TODAY()-J21,"") | L21: =IF(AND(K21<>"",K21>30,NOT(OR(I21="⑤受注",I21="⑦完工",I21="⑥失注"))),"⚠滞留","") | V21: =IF(AND(U21<>"",OR(I21="⑤受注",I21="③見積作成中",I21="④見積提出済")),U21-TODAY(),"") | W21: =IF(V21="","",IF(V21<0,"⚠工期超過",IF(V21<=7,"⚠残り"&V21&"日",""))) | X21: =IF(I21="","",IF(COUNTIFS(請求管理!B:B,A21)>0,"✅発行済","❌未発行")) | Y21: =IF(I21="","",IFERROR(IF(COUNTIFS(請求管理!B:B,A21)=0,"",_xlfn.MAXIFS(請求管理!F:F,請求管理!B:B,A21)),"")) | Z21: =IF(I21="","",IFERROR(IF(COUNTIFS(請求管理!B:B,A21)=0,"",SUMIFS(請求管理!G:G,請求管理!B:B,A21)),"")) | AA21: =IF(I21="","",IF(COUNTIFS(請求管理!B:B,A21)=0,"",IF(SUMIFS(請求管理!J:J,請求管理!B:B,A21)<=0,"✅入金済","❌未入金"))) | AB21: =IF(I21="","",IFERROR(IF(COUNTIFS(請求管理!B:B,A21)=0,"",_xlfn.MAXIFS(請求管理!H:H,請求管理!B:B,A21)),"")) | AC21: =IF(I21="","",IFERROR(IF(COUNTIFS(請求管理!B:B,A21)=0,"",SUMIFS(請求管理!I:I,請求管理!B:B,A21)),"")) | AD21: =IF(OR(I21="⑤受注",I21="⑦完工"),"🟢受注",IF(I21="⑥失注","🔴失注",IF(I21="","","🟡商談中")))
C22: =IFERROR(VLOOKUP(B22,顧客マスタ!A:C,3,FALSE),"") | H22: =IF(AND(F22<>"",G22<>""),(F22-G22)/F22,"") | K22: =IF(J22<>"",TODAY()-J22,"") | L22: =IF(AND(K22<>"",K22>30,NOT(OR(I22="⑤受注",I22="⑦完工",I22="⑥失注"))),"⚠滞留","") | V22: =IF(AND(U22<>"",OR(I22="⑤受注",I22="③見積作成中",I22="④見積提出済")),U22-TODAY(),"") | W22: =IF(V22="","",IF(V22<0,"⚠工期超過",IF(V22<=7,"⚠残り"&V22&"日",""))) | X22: =IF(I22="","",IF(COUNTIFS(請求管理!B:B,A22)>0,"✅発行済","❌未発行")) | Y22: =IF(I22="","",IFERROR(IF(COUNTIFS(請求管理!B:B,A22)=0,"",_xlfn.MAXIFS(請求管理!F:F,請求管理!B:B,A22)),"")) | Z22: =IF(I22="","",IFERROR(IF(COUNTIFS(請求管理!B:B,A22)=0,"",SUMIFS(請求管理!G:G,請求管理!B:B,A22)),"")) | AA22: =IF(I22="","",IF(COUNTIFS(請求管理!B:B,A22)=0,"",IF(SUMIFS(請求管理!J:J,請求管理!B:B,A22)<=0,"✅入金済","❌未入金"))) | AB22: =IF(I22="","",IFERROR(IF(COUNTIFS(請求管理!B:B,A22)=0,"",_xlfn.MAXIFS(請求管理!H:H,請求管理!B:B,A22)),"")) | AC22: =IF(I22="","",IFERROR(IF(COUNTIFS(請求管理!B:B,A22)=0,"",SUMIFS(請求管理!I:I,請求管理!B:B,A22)),"")) | AD22: =IF(OR(I22="⑤受注",I22="⑦完工"),"🟢受注",IF(I22="⑥失注","🔴失注",IF(I22="","","🟡商談中")))
C23: =IFERROR(VLOOKUP(B23,顧客マスタ!A:C,3,FALSE),"") | H23: =IF(AND(F23<>"",G23<>""),(F23-G23)/F23,"") | K23: =IF(J23<>"",TODAY()-J23,"") | L23: =IF(AND(K23<>"",K23>30,NOT(OR(I23="⑤受注",I23="⑦完工",I23="⑥失注"))),"⚠滞留","") | V23: =IF(AND(U23<>"",OR(I23="⑤受注",I23="③見積作成中",I23="④見積提出済")),U23-TODAY(),"") | W23: =IF(V23="","",IF(V23<0,"⚠工期超過",IF(V23<=7,"⚠残り"&V23&"日",""))) | X23: =IF(I23="","",IF(COUNTIFS(請求管理!B:B,A23)>0,"✅発行済","❌未発行")) | Y23: =IF(I23="","",IFERROR(IF(COUNTIFS(請求管理!B:B,A23)=0,"",_xlfn.MAXIFS(請求管理!F:F,請求管理!B:B,A23)),"")) | Z23: =IF(I23="","",IFERROR(IF(COUNTIFS(請求管理!B:B,A23)=0,"",SUMIFS(請求管理!G:G,請求管理!B:B,A23)),"")) | AA23: =IF(I23="","",IF(COUNTIFS(請求管理!B:B,A23)=0,"",IF(SUMIFS(請求管理!J:J,請求管理!B:B,A23)<=0,"✅入金済","❌未入金"))) | AB23: =IF(I23="","",IFERROR(IF(COUNTIFS(請求管理!B:B,A23)=0,"",_xlfn.MAXIFS(請求管理!H:H,請求管理!B:B,A23)),"")) | AC23: =IF(I23="","",IFERROR(IF(COUNTIFS(請求管理!B:B,A23)=0,"",SUMIFS(請求管理!I:I,請求管理!B:B,A23)),"")) | AD23: =IF(OR(I23="⑤受注",I23="⑦完工"),"🟢受注",IF(I23="⑥失注","🔴失注",IF(I23="","","🟡商談中")))
C24: =IFERROR(VLOOKUP(B24,顧客マスタ!A:C,3,FALSE),"") | H24: =IF(AND(F24<>"",G24<>""),(F24-G24)/F24,"") | K24: =IF(J24<>"",TODAY()-J24,"") | L24: =IF(AND(K24<>"",K24>30,NOT(OR(I24="⑤受注",I24="⑦完工",I24="⑥失注"))),"⚠滞留","") | V24: =IF(AND(U24<>"",OR(I24="⑤受注",I24="③見積作成中",I24="④見積提出済")),U24-TODAY(),"") | W24: =IF(V24="","",IF(V24<0,"⚠工期超過",IF(V24<=7,"⚠残り"&V24&"日",""))) | X24: =IF(I24="","",IF(COUNTIFS(請求管理!B:B,A24)>0,"✅発行済","❌未発行")) | Y24: =IF(I24="","",IFERROR(IF(COUNTIFS(請求管理!B:B,A24)=0,"",_xlfn.MAXIFS(請求管理!F:F,請求管理!B:B,A24)),"")) | Z24: =IF(I24="","",IFERROR(IF(COUNTIFS(請求管理!B:B,A24)=0,"",SUMIFS(請求管理!G:G,請求管理!B:B,A24)),"")) | AA24: =IF(I24="","",IF(COUNTIFS(請求管理!B:B,A24)=0,"",IF(SUMIFS(請求管理!J:J,請求管理!B:B,A24)<=0,"✅入金済","❌未入金"))) | AB24: =IF(I24="","",IFERROR(IF(COUNTIFS(請求管理!B:B,A24)=0,"",_xlfn.MAXIFS(請求管理!H:H,請求管理!B:B,A24)),"")) | AC24: =IF(I24="","",IFERROR(IF(COUNTIFS(請求管理!B:B,A24)=0,"",SUMIFS(請求管理!I:I,請求管理!B:B,A24)),"")) | AD24: =IF(OR(I24="⑤受注",I24="⑦完工"),"🟢受注",IF(I24="⑥失注","🔴失注",IF(I24="","","🟡商談中")))
C25: =IFERROR(VLOOKUP(B25,顧客マスタ!A:C,3,FALSE),"") | H25: =IF(AND(F25<>"",G25<>""),(F25-G25)/F25,"") | K25: =IF(J25<>"",TODAY()-J25,"") | L25: =IF(AND(K25<>"",K25>30,NOT(OR(I25="⑤受注",I25="⑦完工",I25="⑥失注"))),"⚠滞留","") | V25: =IF(AND(U25<>"",OR(I25="⑤受注",I25="③見積作成中",I25="④見積提出済")),U25-TODAY(),"") | W25: =IF(V25="","",IF(V25<0,"⚠工期超過",IF(V25<=7,"⚠残り"&V25&"日",""))) | X25: =IF(I25="","",IF(COUNTIFS(請求管理!B:B,A25)>0,"✅発行済","❌未発行")) | Y25: =IF(I25="","",IFERROR(IF(COUNTIFS(請求管理!B:B,A25)=0,"",_xlfn.MAXIFS(請求管理!F:F,請求管理!B:B,A25)),"")) | Z25: =IF(I25="","",IFERROR(IF(COUNTIFS(請求管理!B:B,A25)=0,"",SUMIFS(請求管理!G:G,請求管理!B:B,A25)),"")) | AA25: =IF(I25="","",IF(COUNTIFS(請求管理!B:B,A25)=0,"",IF(SUMIFS(請求管理!J:J,請求管理!B:B,A25)<=0,"✅入金済","❌未入金"))) | AB25: =IF(I25="","",IFERROR(IF(COUNTIFS(請求管理!B:B,A25)=0,"",_xlfn.MAXIFS(請求管理!H:H,請求管理!B:B,A25)),"")) | AC25: =IF(I25="","",IFERROR(IF(COUNTIFS(請求管理!B:B,A25)=0,"",SUMIFS(請求管理!I:I,請求管理!B:B,A25)),"")) | AD25: =IF(OR(I25="⑤受注",I25="⑦完工"),"🟢受注",IF(I25="⑥失注","🔴失注",IF(I25="","","🟡商談中")))
C26: =IFERROR(VLOOKUP(B26,顧客マスタ!A:C,3,FALSE),"") | H26: =IF(AND(F26<>"",G26<>""),(F26-G26)/F26,"") | K26: =IF(J26<>"",TODAY()-J26,"") | L26: =IF(AND(K26<>"",K26>30,NOT(OR(I26="⑤受注",I26="⑦完工",I26="⑥失注"))),"⚠滞留","") | V26: =IF(AND(U26<>"",OR(I26="⑤受注",I26="③見積作成中",I26="④見積提出済")),U26-TODAY(),"") | W26: =IF(V26="","",IF(V26<0,"⚠工期超過",IF(V26<=7,"⚠残り"&V26&"日",""))) | X26: =IF(I26="","",IF(COUNTIFS(請求管理!B:B,A26)>0,"✅発行済","❌未発行")) | Y26: =IF(I26="","",IFERROR(IF(COUNTIFS(請求管理!B:B,A26)=0,"",_xlfn.MAXIFS(請求管理!F:F,請求管理!B:B,A26)),"")) | Z26: =IF(I26="","",IFERROR(IF(COUNTIFS(請求管理!B:B,A26)=0,"",SUMIFS(請求管理!G:G,請求管理!B:B,A26)),"")) | AA26: =IF(I26="","",IF(COUNTIFS(請求管理!B:B,A26)=0,"",IF(SUMIFS(請求管理!J:J,請求管理!B:B,A26)<=0,"✅入金済","❌未入金"))) | AB26: =IF(I26="","",IFERROR(IF(COUNTIFS(請求管理!B:B,A26)=0,"",_xlfn.MAXIFS(請求管理!H:H,請求管理!B:B,A26)),"")) | AC26: =IF(I26="","",IFERROR(IF(COUNTIFS(請求管理!B:B,A26)=0,"",SUMIFS(請求管理!I:I,請求管理!B:B,A26)),"")) | AD26: =IF(OR(I26="⑤受注",I26="⑦完工"),"🟢受注",IF(I26="⑥失注","🔴失注",IF(I26="","","🟡商談中")))
C27: =IFERROR(VLOOKUP(B27,顧客マスタ!A:C,3,FALSE),"") | H27: =IF(AND(F27<>"",G27<>""),(F27-G27)/F27,"") | K27: =IF(J27<>"",TODAY()-J27,"") | L27: =IF(AND(K27<>"",K27>30,NOT(OR(I27="⑤受注",I27="⑦完工",I27="⑥失注"))),"⚠滞留","") | V27: =IF(AND(U27<>"",OR(I27="⑤受注",I27="③見積作成中",I27="④見積提出済")),U27-TODAY(),"") | W27: =IF(V27="","",IF(V27<0,"⚠工期超過",IF(V27<=7,"⚠残り"&V27&"日",""))) | X27: =IF(I27="","",IF(COUNTIFS(請求管理!B:B,A27)>0,"✅発行済","❌未発行")) | Y27: =IF(I27="","",IFERROR(IF(COUNTIFS(請求管理!B:B,A27)=0,"",_xlfn.MAXIFS(請求管理!F:F,請求管理!B:B,A27)),"")) | Z27: =IF(I27="","",IFERROR(IF(COUNTIFS(請求管理!B:B,A27)=0,"",SUMIFS(請求管理!G:G,請求管理!B:B,A27)),"")) | AA27: =IF(I27="","",IF(COUNTIFS(請求管理!B:B,A27)=0,"",IF(SUMIFS(請求管理!J:J,請求管理!B:B,A27)<=0,"✅入金済","❌未入金"))) | AB27: =IF(I27="","",IFERROR(IF(COUNTIFS(請求管理!B:B,A27)=0,"",_xlfn.MAXIFS(請求管理!H:H,請求管理!B:B,A27)),"")) | AC27: =IF(I27="","",IFERROR(IF(COUNTIFS(請求管理!B:B,A27)=0,"",SUMIFS(請求管理!I:I,請求管理!B:B,A27)),"")) | AD27: =IF(OR(I27="⑤受注",I27="⑦完工"),"🟢受注",IF(I27="⑥失注","🔴失注",IF(I27="","","🟡商談中")))
C28: =IFERROR(VLOOKUP(B28,顧客マスタ!A:C,3,FALSE),"") | H28: =IF(AND(F28<>"",G28<>""),(F28-G28)/F28,"") | K28: =IF(J28<>"",TODAY()-J28,"") | L28: =IF(AND(K28<>"",K28>30,NOT(OR(I28="⑤受注",I28="⑦完工",I28="⑥失注"))),"⚠滞留","") | V28: =IF(AND(U28<>"",OR(I28="⑤受注",I28="③見積作成中",I28="④見積提出済")),U28-TODAY(),"") | W28: =IF(V28="","",IF(V28<0,"⚠工期超過",IF(V28<=7,"⚠残り"&V28&"日",""))) | X28: =IF(I28="","",IF(COUNTIFS(請求管理!B:B,A28)>0,"✅発行済","❌未発行")) | Y28: =IF(I28="","",IFERROR(IF(COUNTIFS(請求管理!B:B,A28)=0,"",_xlfn.MAXIFS(請求管理!F:F,請求管理!B:B,A28)),"")) | Z28: =IF(I28="","",IFERROR(IF(COUNTIFS(請求管理!B:B,A28)=0,"",SUMIFS(請求管理!G:G,請求管理!B:B,A28)),"")) | AA28: =IF(I28="","",IF(COUNTIFS(請求管理!B:B,A28)=0,"",IF(SUMIFS(請求管理!J:J,請求管理!B:B,A28)<=0,"✅入金済","❌未入金"))) | AB28: =IF(I28="","",IFERROR(IF(COUNTIFS(請求管理!B:B,A28)=0,"",_xlfn.MAXIFS(請求管理!H:H,請求管理!B:B,A28)),"")) | AC28: =IF(I28="","",IFERROR(IF(COUNTIFS(請求管理!B:B,A28)=0,"",SUMIFS(請求管理!I:I,請求管理!B:B,A28)),"")) | AD28: =IF(OR(I28="⑤受注",I28="⑦完工"),"🟢受注",IF(I28="⑥失注","🔴失注",IF(I28="","","🟡商談中")))
... C96: =IFERROR(VLOOKUP(B96,顧客マスタ!A:C,3,FALSE),"") | H96: =IF(AND(F96<>"",G96<>""),(F96-G96)/F96,"") | K96: =IF(J96<>"",TODAY()-J96,"") | L96: =IF(AND(K96<>"",K96>30,NOT(OR(I96="⑤受注",I96="⑦完工",I96="⑥失注"))),"⚠滞留","") | V96: =IF(AND(U96<>"",OR(I96="⑤受注",I96="③見積作成中",I96="④見積提出済")),U96-TODAY(),"") | W96: =IF(V96="","",IF(V96<0,"⚠工期超過",IF(V96<=7,"⚠残り"&V96&"日",""))) | X96: =IF(I96="","",IF(COUNTIFS(請求管理!B:B,A96)>0,"✅発行済","❌未発行")) | Y96: =IF(I96="","",IFERROR(IF(COUNTIFS(請求管理!B:B,A96)=0,"",_xlfn.MAXIFS(請求管理!F:F,請求管理!B:B,A96)),"")) | Z96: =IF(I96="","",IFERROR(IF(COUNTIFS(請求管理!B:B,A96)=0,"",SUMIFS(請求管理!G:G,請求管理!B:B,A96)),"")) | AA96: =IF(I96="","",IF(COUNTIFS(請求管理!B:B,A96)=0,"",IF(SUMIFS(請求管理!J:J,請求管理!B:B,A96)<=0,"✅入金済","❌未入金"))) | AB96: =IF(I96="","",IFERROR(IF(COUNTIFS(請求管理!B:B,A96)=0,"",_xlfn.MAXIFS(請求管理!H:H,請求管理!B:B,A96)),"")) | AC96: =IF(I96="","",IFERROR(IF(COUNTIFS(請求管理!B:B,A96)=0,"",SUMIFS(請求管理!I:I,請求管理!B:B,A96)),"")) | AD96: =IF(OR(I96="⑤受注",I96="⑦完工"),"🟢受注",IF(I96="⑥失注","🔴失注",IF(I96="","","🟡商談中")))

Sheet Ｓ表紙
I1: ▼ 案件切替 | J1: ▼ 案件切替（J2にシート名を入力→Claudeに「S表紙切替」と依頼）
I2: シート名▶ | J2: P-003_吉野様邸キッチン
I3: 案件ID▶ | J3: P-003
B5: 御 見 積 書 | G5: 株式会社LinK
G6: 〒134-0081 東京都江戸川区北葬西1丁目2番22号
G7: TEL: 03-6825-2464 | J7: =TODAY() -> 46070
C10: =IFERROR(VLOOKUP($J$3,案件管理!A:D,3,FALSE),"") -> 矢島不動産管理株式会社 | F10: =IFERROR(VLOOKUP(VLOOKUP($J$3,案件管理!A:B,2,FALSE),顧客マスタ!A:D,4,FALSE),"様") -> 御中 | H10: エントランス以外 追加工事
E14: 御見積金額 | F14: ￥ | G14: =I61 -> 1573406 | I14: （税込）
C20: 工事名： | D20: =IFERROR(VLOOKUP($J$3,案件管理!A:D,4,FALSE),"") -> 吉野様邸 キッチンリフォーム
C22: 工 場 所 ： | D22: =操作パネル!F8 -> 東京都港区南麻布
C24: 有効期間 ： | D24: 30日間
C26: 別途工事 ： | D26: 見積記載無き項目
A32: 内 訳 明 細 書
A35: Ｎｏ， | B35: 名称形状 | F35: 数量 | G35: 単位 | H35: 単価 | I35: 金額 | J35: 備考
A36: 1 | B36: 解体工事 | I36: ='P-003_吉野様邸キッチン'!B105 -> 113333
A37: 2 | B37: 造作工事 | I37: ='P-003_吉野様邸キッチン'!B106 -> 0
A38: 3 | B38: 建具工事 | I38: ='P-003_吉野様邸キッチン'!B107 -> 0
A39: 4 | B39: 家具工事 | I39: ='P-003_吉野様邸キッチン'!B108 -> 680000
A40: 5 | B40: 電気設備 | I40: ='P-003_吉野様邸キッチン'!B109 -> 86667
A41: 6 | B41: タイル左官工事 | I41: ='P-003_吉野様邸キッチン'!B110 -> 0
A42: 7 | B42: 仕上げ工事 | I42: ='P-003_吉野様邸キッチン'!B111 -> 52400
A43: 8 | B43: 衛生設備 | I43: ='P-003_吉野様邸キッチン'!B112 -> 160000
A44: 9 | B44: 共通 | I44: ='P-003_吉野様邸キッチン'!B113 -> 48000
A45: 10 | B45: 下地工事 | I45: ='P-003_吉野様邸キッチン'!B114 -> 0
A46: 11 | B46: 新規壁工事 | I46: ='P-003_吉野様邸キッチン'!B115 -> 0
A47: 12 | B47: 床 | I47: ='P-003_吉野様邸キッチン'!B116 -> 0 | K47: 0
A48: 13 | B48: 空調 | I48: ='P-003_吉野様邸キッチン'!B117 -> 0
A49: 14 | B49: シート工事 | I49: ='P-003_吉野様邸キッチン'!B118 -> 0
A50: 15 | B50: 塗装工事 | I50: ='P-003_吉野様邸キッチン'!B119 -> 0
A51: 16 | B51: 雑工事 | I51: ='P-003_吉野様邸キッチン'!B120 -> 0
A52: 17 | B52: 防災工事 | I52: ='P-003_吉野様邸キッチン'!B121 -> 0
A53: 18 | B53: ガス工事 | I53: ='P-003_吉野様邸キッチン'!B122 -> 0
A54: 19 | B54: 産廃費 | I54: ='P-003_吉野様邸キッチン'!B123 -> 0
A55: 20 | B55: 仮設工事 | I55: ='P-003_吉野様邸キッチン'!B124 -> 0
A56: 21 | B56: 会社経費 | F56: =マスター設定!K20*100 -> 10 | G56: ％ | H56: =マスター設定!K22 -> 25000 | I56: =SUM(I36:I54)*マスター設定!K20 -> 114040
A57: 22 | B57: 現場経費 | F57: =マスター設定!K21*100 -> 5 | G57: ％ | H57: =マスター設定!K22 -> 25000 | I57: =SUM(I36:I54)*マスター設定!K21 -> 57020
A58: 23 | B58: 現場管理費 | F58: =マスター設定!K23 -> 5 | G58: 人工 | H58: =マスター設定!K22 -> 25000 | I58: =マスター設定!K23*マスター設定!K22 -> 125000
A59: 24 | B59: 消費税 | F59: 10 | G59: ％ | I59: =SUM(I36:I58)*マスター設定!K24 -> 143646
A60: 25 | I60: -6700
B61: 小計 | I61: =SUM(I36:I60) -> 1573406

Sheet P-003_吉野様邸キッチン
A1: P-003 吉野様邸 キッチンリフォーム
A2: ※ 新規案件作成時にこのシートを複製して使用します
A4: ▼ 案件基本情報
A5: 案件ID | B5: P-003 | D5: 顧客ID | E5: C-001 | F5: 顧客名 | G5: =IFERROR(VLOOKUP(E5,顧客マスタ!A:C,3,FALSE),"") -> 矢島不動産管理株式会社 | I5: 敬称 | J5: =IFERROR(VLOOKUP(E5,顧客マスタ!A:D,4,FALSE),"") -> 御中 | M5: 担当者 | N5: 吉野博
A6: 工事名 | B6: 吉野様邸 キッチンリフォーム | F6: 施工場所 | G6: 東京都港区南麻布 | M6: 作成日 | N6: =TODAY() -> 46070
A7: 目標粗利率 | B7: 0.25 | D7: ※原価逆算型のデフォルト
A9: ▼ 原価管理表（見積 → 原価 → 客出し金額 → 発注管理）
A11: ※ A=原価逆算型（原価÷(1-粗利率)） B=定価固定型（客出し固定） C=単価固定型（クロス等市場単価×数量）
A12: 青字=手入力 黒字=自動計算 ★=発注情報 ◆E/F/H列はDB自動参照（上書きOK）
B13: 原価情報 | H13: 客出し情報 | L13: 利益 | N13: ★ 発注管理
A14: No. | B14: タイプ | C14: 工事カテゴリ | D14: 品名（小項目） | E14: 仕様・形状 | F14: 原価単価 | G14: 原価金額 | H14: 単位 | I14: 数量 | J14: 客出し単価 | K14: 客出し金額 | L14: 利益額 | M14: 利益率 | N14: 発注先 | O14: 発注日 | P14: 発注額 | Q14: 支払済 | R14: 備考
A15: 1 | B15: A | C15: 解体工事 | D15: 既存キッチン解体・撤去 | E15: 材工共 | F15: 85000 | G15: =IF(F15<>"",F15*I15,"") -> 85000 | H15: 式 | I15: 1 | J15: =IF(B15="A",IF(AND(F15<>"",I15<>""),ROUND(F15/(1-$B$7),0),""),"") -> 113333 | K15: =IF(AND(J15<>"",I15<>""),J15*I15,"") -> 113333 | L15: =IF(AND(K15<>"",G15<>""),K15-G15,"") -> 28333 | M15: =IF(AND(K15<>"",K15<>0),L15/K15,"") -> 0.24999779 | P15: =IF(N15<>"",G15,"")
A16: 2 | B16: A | C16: 衛生設備 | D16: 給排水配管工事 | E16: 材工共 | F16: 120000 | G16: =IF(F16<>"",F16*I16,"") -> 120000 | H16: 式 | I16: 1 | J16: =IF(B16="A",IF(AND(F16<>"",I16<>""),ROUND(F16/(1-$B$7),0),""),"") -> 160000 | K16: =IF(AND(J16<>"",I16<>""),J16*I16,"") -> 160000 | L16: =IF(AND(K16<>"",G16<>""),K16-G16,"") -> 40000 | M16: =IF(AND(K16<>"",K16<>0),L16/K16,"") -> 0.25 | P16: =IF(N16<>"",G16,"")
A17: 3 | B17: B | C17: 家具工事 | D17: LIXIL システムキッチン シエラS | E17: W2550 IH・食洗機付 | F17: 420000 | G17: =IF(F17<>"",F17*I17,"") -> 420000 | H17: 台 | I17: 1 | J17: 680000 | K17: =IF(AND(J17<>"",I17<>""),J17*I17,"") -> 680000 | L17: =IF(AND(K17<>"",G17<>""),K17-G17,"") -> 260000 | M17: =IF(AND(K17<>"",K17<>0),L17/K17,"") -> 0.38235294 | P17: =IF(N17<>"",G17,"")
A18: 4 | B18: C | C18: 仕上げ工事 | D18: クロス張替え | E18: 量産クロス SP級 | F18: 650 | G18: =IF(F18<>"",F18*I18,"") -> 18200 | H18: ㎡ | I18: 28 | J18: 1100 | K18: =IF(AND(J18<>"",I18<>""),J18*I18,"") -> 30800 | L18: =IF(AND(K18<>"",G18<>""),K18-G18,"") -> 12600 | M18: =IF(AND(K18<>"",K18<>0),L18/K18,"") -> 0.40909091 | P18: =IF(N18<>"",G18,"")
A19: 5 | B19: C | C19: 仕上げ工事 | D19: CFシート張替え | E19: サンゲツ HM-10108 | F19: 800 | G19: =IF(F19<>"",F19*I19,"") -> 9600 | H19: ㎡ | I19: 12 | J19: 1800 | K19: =IF(AND(J19<>"",I19<>""),J19*I19,"") -> 21600 | L19: =IF(AND(K19<>"",G19<>""),K19-G19,"") -> 12000 | M19: =IF(AND(K19<>"",K19<>0),L19/K19,"") -> 0.55555556 | P19: =IF(N19<>"",G19,"")
A20: 6 | B20: A | C20: 電気設備 | D20: コンセント増設・照明移設 | E20: 材工共 | F20: 65000 | G20: =IF(F20<>"",F20*I20,"") -> 65000 | H20: 式 | I20: 1 | J20: =IF(B20="A",IF(AND(F20<>"",I20<>""),ROUND(F20/(1-$B$7),0),""),"") -> 86667 | K20: =IF(AND(J20<>"",I20<>""),J20*I20,"") -> 86667 | L20: =IF(AND(K20<>"",G20<>""),K20-G20,"") -> 21667 | M20: =IF(AND(K20<>"",K20<>0),L20/K20,"") -> 0.25000288 | P20: =IF(N20<>"",G20,"")
A21: 7 | B21: A | C21: 共通 | D21: 産廃処理費 | E21: 混載 | F21: 18000 | G21: =IF(F21<>"",F21*I21,"") -> 36000 | H21: ㎥ | I21: 2 | J21: =IF(B21="A",IF(AND(F21<>"",I21<>""),ROUND(F21/(1-$B$7),0),""),"") -> 24000 | K21: =IF(AND(J21<>"",I21<>""),J21*I21,"") -> 48000 | L21: =IF(AND(K21<>"",G21<>""),K21-G21,"") -> 12000 | M21: =IF(AND(K21<>"",K21<>0),L21/K21,"") -> 0.25 | P21: =IF(N21<>"",G21,"")
A22: 8 | E22: =IF(AND(C22<>"",D22<>""),IFERROR(INDEX(工事項目DB!D:D,MATCH(C22&"|"&D22,工事項目DB!L:L,0)),""),"") | F22: =IF(AND(C22<>"",D22<>""),IFERROR(INDEX(工事項目DB!F:F,MATCH(C22&"|"&D22,工事項目DB!L:L,0)),""),"") | G22: =IF(F22<>"",F22*I22,"") | H22: =IF(AND(C22<>"",D22<>""),IFERROR(INDEX(工事項目DB!E:E,MATCH(C22&"|"&D22,工事項目DB!L:L,0)),""),"") | J22: =IF(B22="A",IF(AND(F22<>"",I22<>""),ROUND(F22/(1-$B$7),0),""),"") | K22: =IF(AND(J22<>"",I22<>""),J22*I22,"") | L22: =IF(AND(K22<>"",G22<>""),K22-G22,"") | M22: =IF(AND(K22<>"",K22<>0),L22/K22,"") | P22: =IF(N22<>"",G22,"")
A23: 9 | E23: =IF(AND(C23<>"",D23<>""),IFERROR(INDEX(工事項目DB!D:D,MATCH(C23&"|"&D23,工事項目DB!L:L,0)),""),"") | F23: =IF(AND(C23<>"",D23<>""),IFERROR(INDEX(工事項目DB!F:F,MATCH(C23&"|"&D23,工事項目DB!L:L,0)),""),"") | G23: =IF(F23<>"",F23*I23,"") | H23: =IF(AND(C23<>"",D23<>""),IFERROR(INDEX(工事項目DB!E:E,MATCH(C23&"|"&D23,工事項目DB!L:L,0)),""),"") | J23: =IF(B23="A",IF(AND(F23<>"",I23<>""),ROUND(F23/(1-$B$7),0),""),"") | K23: =IF(AND(J23<>"",I23<>""),J23*I23,"") | L23: =IF(AND(K23<>"",G23<>""),K23-G23,"") | M23: =IF(AND(K23<>"",K23<>0),L23/K23,"") | P23: =IF(N23<>"",G23,"")
A24: 10 | E24: =IF(AND(C24<>"",D24<>""),IFERROR(INDEX(工事項目DB!D:D,MATCH(C24&"|"&D24,工事項目DB!L:L,0)),""),"") | F24: =IF(AND(C24<>"",D24<>""),IFERROR(INDEX(工事項目DB!F:F,MATCH(C24&"|"&D24,工事項目DB!L:L,0)),""),"") | G24: =IF(F24<>"",F24*I24,"") | H24: =IF(AND(C24<>"",D24<>""),IFERROR(INDEX(工事項目DB!E:E,MATCH(C24&"|"&D24,工事項目DB!L:L,0)),""),"") | J24: =IF(B24="A",IF(AND(F24<>"",I24<>""),ROUND(F24/(1-$B$7),0),""),"") | K24: =IF(AND(J24<>"",I24<>""),J24*I24,"") | L24: =IF(AND(K24<>"",G24<>""),K24-G24,"") | M24: =IF(AND(K24<>"",K24<>0),L24/K24,"") | P24: =IF(N24<>"",G24,"")
A25: 11 | E25: =IF(AND(C25<>"",D25<>""),IFERROR(INDEX(工事項目DB!D:D,MATCH(C25&"|"&D25,工事項目DB!L:L,0)),""),"") | F25: =IF(AND(C25<>"",D25<>""),IFERROR(INDEX(工事項目DB!F:F,MATCH(C25&"|"&D25,工事項目DB!L:L,0)),""),"") | G25: =IF(F25<>"",F25*I25,"") | H25: =IF(AND(C25<>"",D25<>""),IFERROR(INDEX(工事項目DB!E:E,MATCH(C25&"|"&D25,工事項目DB!L:L,0)),""),"") | J25: =IF(B25="A",IF(AND(F25<>"",I25<>""),ROUND(F25/(1-$B$7),0),""),"") | K25: =IF(AND(J25<>"",I25<>""),J25*I25,"") | L25: =IF(AND(K25<>"",G25<>""),K25-G25,"") | M25: =IF(AND(K25<>"",K25<>0),L25/K25,"") | P25: =IF(N25<>"",G25,"")
A26: 12 | E26: =IF(AND(C26<>"",D26<>""),IFERROR(INDEX(工事項目DB!D:D,MATCH(C26&"|"&D26,工事項目DB!L:L,0)),""),"") | F26: =IF(AND(C26<>"",D26<>""),IFERROR(INDEX(工事項目DB!F:F,MATCH(C26&"|"&D26,工事項目DB!L:L,0)),""),"") | G26: =IF(F26<>"",F26*I26,"") | H26: =IF(AND(C26<>"",D26<>""),IFERROR(INDEX(工事項目DB!E:E,MATCH(C26&"|"&D26,工事項目DB!L:L,0)),""),"") | J26: =IF(B26="A",IF(AND(F26<>"",I26<>""),ROUND(F26/(1-$B$7),0),""),"") | K26: =IF(AND(J26<>"",I26<>""),J26*I26,"") | L26: =IF(AND(K26<>"",G26<>""),K26-G26,"") | M26: =IF(AND(K26<>"",K26<>0),L26/K26,"") | P26: =IF(N26<>"",G26,"")
A27: 13 | E27: =IF(AND(C27<>"",D27<>""),IFERROR(INDEX(工事項目DB!D:D,MATCH(C27&"|"&D27,工事項目DB!L:L,0)),""),"") | F27: =IF(AND(C27<>"",D27<>""),IFERROR(INDEX(工事項目DB!F:F,MATCH(C27&"|"&D27,工事項目DB!L:L,0)),""),"") | G27: =IF(F27<>"",F27*I27,"") | H27: =IF(AND(C27<>"",D27<>""),IFERROR(INDEX(工事項目DB!E:E,MATCH(C27&"|"&D27,工事項目DB!L:L,0)),""),"") | J27: =IF(B27="A",IF(AND(F27<>"",I27<>""),ROUND(F27/(1-$B$7),0),""),"") | K27: =IF(AND(J27<>"",I27<>""),J27*I27,"") | L27: =IF(AND(K27<>"",G27<>""),K27-G27,"") | M27: =IF(AND(K27<>"",K27<>0),L27/K27,"") | P27: =IF(N27<>"",G27,"")
A28: 14 | E28: =IF(AND(C28<>"",D28<>""),IFERROR(INDEX(工事項目DB!D:D,MATCH(C28&"|"&D28,工事項目DB!L:L,0)),""),"") | F28: =IF(AND(C28<>"",D28<>""),IFERROR(INDEX(工事項目DB!F:F,MATCH(C28&"|"&D28,工事項目DB!L:L,0)),""),"") | G28: =IF(F28<>"",F28*I28,"") | H28: =IF(AND(C28<>"",D28<>""),IFERROR(INDEX(工事項目DB!E:E,MATCH(C28&"|"&D28,工事項目DB!L:L,0)),""),"") | J28: =IF(B28="A",IF(AND(F28<>"",I28<>""),ROUND(F28/(1-$B$7),0),""),"") | K28: =IF(AND(J28<>"",I28<>""),J28*I28,"") | L28: =IF(AND(K28<>"",G28<>""),K28-G28,"") | M28: =IF(AND(K28<>"",K28<>0),L28/K28,"") | P28: =IF(N28<>"",G28,"")
A29: 15 | E29: =IF(AND(C29<>"",D29<>""),IFERROR(INDEX(工事項目DB!D:D,MATCH(C29&"|"&D29,工事項目DB!L:L,0)),""),"") | F29: =IF(AND(C29<>"",D29<>""),IFERROR(INDEX(工事項目DB!F:F,MATCH(C29&"|"&D29,工事項目DB!L:L,0)),""),"") | G29: =IF(F29<>"",F29*I29,"") | H29: =IF(AND(C29<>"",D29<>""),IFERROR(INDEX(工事項目DB!E:E,MATCH(C29&"|"&D29,工事項目DB!L:L,0)),""),"") | J29: =IF(B29="A",IF(AND(F29<>"",I29<>""),ROUND(F29/(1-$B$7),0),""),"") | K29: =IF(AND(J29<>"",I29<>""),J29*I29,"") | L29: =IF(AND(K29<>"",G29<>""),K29-G29,"") | M29: =IF(AND(K29<>"",K29<>0),L29/K29,"") | P29: =IF(N29<>"",G29,"")
A30: 16 | E30: =IF(AND(C30<>"",D30<>""),IFERROR(INDEX(工事項目DB!D:D,MATCH(C30&"|"&D30,工事項目DB!L:L,0)),""),"") | F30: =IF(AND(C30<>"",D30<>""),IFERROR(INDEX(工事項目DB!F:F,MATCH(C30&"|"&D30,工事項目DB!L:L,0)),""),"") | G30: =IF(F30<>"",F30*I30,"") | H30: =IF(AND(C30<>"",D30<>""),IFERROR(INDEX(工事項目DB!E:E,MATCH(C30&"|"&D30,工事項目DB!L:L,0)),""),"") | J30: =IF(B30="A",IF(AND(F30<>"",I30<>""),ROUND(F30/(1-$B$7),0),""),"") | K30: =IF(AND(J30<>"",I30<>""),J30*I30,"") | L30: =IF(AND(K30<>"",G30<>""),K30-G30,"") | M30: =IF(AND(K30<>"",K30<>0),L30/K30,"") | P30: =IF(N30<>"",G30,"")
A31: 17 | E31: =IF(AND(C31<>"",D31<>""),IFERROR(INDEX(工事項目DB!D:D,MATCH(C31&"|"&D31,工事項目DB!L:L,0)),""),"") | F31: =IF(AND(C31<>"",D31<>""),IFERROR(INDEX(工事項目DB!F:F,MATCH(C31&"|"&D31,工事項目DB!L:L,0)),""),"") | G31: =IF(F31<>"",F31*I31,"") | H31: =IF(AND(C31<>"",D31<>""),IFERROR(INDEX(工事項目DB!E:E,MATCH(C31&"|"&D31,工事項目DB!L:L,0)),""),"") | J31: =IF(B31="A",IF(AND(F31<>"",I31<>""),ROUND(F31/(1-$B$7),0),""),"") | K31: =IF(AND(J31<>"",I31<>""),J31*I31,"") | L31: =IF(AND(K31<>"",G31<>""),K31-G31,"") | M31: =IF(AND(K31<>"",K31<>0),L31/K31,"") | P31: =IF(N31<>"",G31,"")
A32: 18 | E32: =IF(AND(C32<>"",D32<>""),IFERROR(INDEX(工事項目DB!D:D,MATCH(C32&"|"&D32,工事項目DB!L:L,0)),""),"") | F32: =IF(AND(C32<>"",D32<>""),IFERROR(INDEX(工事項目DB!F:F,MATCH(C32&"|"&D32,工事項目DB!L:L,0)),""),"") | G32: =IF(F32<>"",F32*I32,"") | H32: =IF(AND(C32<>"",D32<>""),IFERROR(INDEX(工事項目DB!E:E,MATCH(C32&"|"&D32,工事項目DB!L:L,0)),""),"") | J32: =IF(B32="A",IF(AND(F32<>"",I32<>""),ROUND(F32/(1-$B$7),0),""),"") | K32: =IF(AND(J32<>"",I32<>""),J32*I32,"") | L32: =IF(AND(K32<>"",G32<>""),K32-G32,"") | M32: =IF(AND(K32<>"",K32<>0),L32/K32,"") | P32: =IF(N32<>"",G32,"")
A33: 19 | E33: =IF(AND(C33<>"",D33<>""),IFERROR(INDEX(工事項目DB!D:D,MATCH(C33&"|"&D33,工事項目DB!L:L,0)),""),"") | F33: =IF(AND(C33<>"",D33<>""),IFERROR(INDEX(工事項目DB!F:F,MATCH(C33&"|"&D33,工事項目DB!L:L,0)),""),"") | G33: =IF(F33<>"",F33*I33,"") | H33: =IF(AND(C33<>"",D33<>""),IFERROR(INDEX(工事項目DB!E:E,MATCH(C33&"|"&D33,工事項目DB!L:L,0)),""),"") | J33: =IF(B33="A",IF(AND(F33<>"",I33<>""),ROUND(F33/(1-$B$7),0),""),"") | K33: =IF(AND(J33<>"",I33<>""),J33*I33,"") | L33: =IF(AND(K33<>"",G33<>""),K33-G33,"") | M33: =IF(AND(K33<>"",K33<>0),L33/K33,"") | P33: =IF(N33<>"",G33,"")
... A44: 30 | E44: =IF(AND(C44<>"",D44<>""),IFERROR(INDEX(工事項目DB!D:D,MATCH(C44&"|"&D44,工事項目DB!L:L,0)),""),"") | F44: =IF(AND(C44<>"",D44<>""),IFERROR(INDEX(工事項目DB!F:F,MATCH(C44&"|"&D44,工事項目DB!L:L,0)),""),"") | G44: =IF(F44<>"",F44*I44,"") | H44: =IF(AND(C44<>"",D44<>""),IFERROR(INDEX(工事項目DB!E:E,MATCH(C44&"|"&D44,工事項目DB!L:L,0)),""),"") | J44: =IF(B44="A",IF(AND(F44<>"",I44<>""),ROUND(F44/(1-$B$7),0),""),"") | K44: =IF(AND(J44<>"",I44<>""),J44*I44,"") | L44: =IF(AND(K44<>"",G44<>""),K44-G44,"") | M44: =IF(AND(K44<>"",K44<>0),L44/K44,"") | P44: =IF(N44<>"",G44,"")
F45: 原価合計 | G45: =SUM(G15:G44) -> 753800 | J45: 客出し合計 | K45: =SUM(K15:K44) -> 1140400 | L45: =K45-G45 -> 386600 | M45: =IF(K45<>0,L45/K45,"") -> 0.33900386 | P45: =SUM(P15:P44) -> 0
A47: ▼ 税計算
A48: 小計（税抜） | G48: =G45 -> 753800 | K48: =K45 -> 1140400 | L48: =L45 -> 386600 | M48: =M45 -> 0.33900386
A49: 消費税（10%） | G49: =ROUND(G48*マスター設定!K24,0) -> 75380 | K49: =ROUND(K48*マスター設定!K24,0) -> 114040
A50: 合計（税込） | G50: =G48+G49 -> 829180 | K50: =K48+K49 -> 1254440 | L50: =K50-G50 -> 425260 | M50: =IF(K50<>0,L50/K50,"") -> 0.33900386
A53: ▼ 行操作ツール
A54: クリアしたい行No. | C54: ← 行No.を入力してClaudeに「行クリア」と伝えてください
A55: 入替え: 行A ↔ 行B | C55: ← | E55: ← 2つのNo.を入力してClaudeに「行入替え」と伝えてください
A56: ※ 直接セルを選択してDeleteキーでもクリアできます（数式は自動復元）
...

Sheet 発注書兼請求書
A1: 帳票切替 | B1: 発注書 | C1: 案件ID▶ | D1: P-003 | E1: 業者ID▶ | G1: 1
A3: =IF(B1="発注書","【 発 注 書 】","【 請 求 書 】") -> 【 発 注 書 】
A5: 宛先業者 | B5: =IFERROR(VLOOKUP(G1,業者DB!A:B,2,FALSE),"") -> 株式会社M-Pros | F5: 御中 | G5: 株式会社LinK
B6: =IFERROR(VLOOKUP(B5,業者DB!B:F,3,FALSE)&" "&VLOOKUP(B5,業者DB!B:F,4,FALSE),"") | G6: 〒134-0081 東京都江戸川区北葛西1-2-22
G7: TEL: 03-6825-2464
G8: Email: info@link-8.jp
A10: 施 工 場 所 | B10: =IFERROR(VLOOKUP(D1,案件管理!A:E,5,FALSE),"") -> キッチン設備・内装 | G10: =IF(B1="発注書","発 注 日","請 求 日") -> 発 注 日 | H10: =TODAY() -> 46070
A11: 工 事 件 名 | B11: =IFERROR(VLOOKUP(D1,案件管理!A:D,4,FALSE),"") -> 吉野様邸 キッチンリフォーム | G11: =IF(B1="請求書","支 払 期 日","")
A12: 受 渡 期 限
A13: 支 払 条 件 | B13: =IFERROR(VLOOKUP(G1,業者DB!A:I,9,FALSE),"") -> 0 | H13: 【社判】
A14: 総 金 額 | B14: ￥ | D14: =I42 -> 0 | F14: （税込）
A16: =IF(B1="発注書","下記の通り発注いたします。","下記の通りご請求申し上げます。") -> 下記の通り発注いたします。
A18: No. | B18: 名称 | D18: 仕様・形状 | F18: 数量 | G18: 単位 | H18: 単価 | I18: 金額
A19: 1 | I19: =IF(AND(F19<>"",H19<>""),F19*H19,"")
A20: 2 | I20: =IF(AND(F20<>"",H20<>""),F20*H20,"")
A21: 3 | I21: =IF(AND(F21<>"",H21<>""),F21*H21,"")
A22: 4 | I22: =IF(AND(F22<>"",H22<>""),F22*H22,"")
A23: 5 | I23: =IF(AND(F23<>"",H23<>""),F23*H23,"")
A24: 6 | I24: =IF(AND(F24<>"",H24<>""),F24*H24,"")
A25: 7 | I25: =IF(AND(F25<>"",H25<>""),F25*H25,"")
A26: 8 | I26: =IF(AND(F26<>"",H26<>""),F26*H26,"")
A27: 9 | I27: =IF(AND(F27<>"",H27<>""),F27*H27,"")
A28: 10 | I28: =IF(AND(F28<>"",H28<>""),F28*H28,"")
A29: 11 | I29: =IF(AND(F29<>"",H29<>""),F29*H29,"")
A30: 12 | I30: =IF(AND(F30<>"",H30<>""),F30*H30,"")
... A38: 20 | I38: =IF(AND(F38<>"",H38<>""),F38*H38,"")
A39: 小 計 | I39: =SUM(I19:I38) -> 0
A40: 消費税（10%） | I40: =ROUND(I39*マスター設定!K24,0) -> 0
A42: 合 計（税込） | I42: =I39+I40 -> 0
A44: =IF(B1="請求書","【 振込口座 】","")
A47: =IF(B1="請求書","お振込手数料のご負担をお願い申し上げます。","※ 本発注書記載の金額にてご請求をお願いいたします。") -> ※ 本発注書記載の金額にてご請求をお願いいたします。

Sheet 領収書
A1: 領収書 | I1: ▼ 入力エリア
I2: 請求ID | K2: ←入力
G3: No. | H3: =IF(J2="","","R-"&MID(J2,5,3)) | I3: 案件ID | J3: =IF(J2="","",IFERROR(VLOOKUP(J2,請求管理!A:B,2,FALSE),""))
I4: 案件名 | J4: =IF(J2="","",IFERROR(VLOOKUP(J2,請求管理!A:C,3,FALSE),""))
B5: 領 収 書 | I5: 顧客名 | J5: =IF(J2="","",IFERROR(VLOOKUP(J2,請求管理!A:D,4,FALSE),""))
B7: =IF(J5="","",J5) | E7: 様
G8: 発行日 | H8: =IF(J2="","",TODAY())
B10: 金 額 | D10: =IF(J2="","",IFERROR(VLOOKUP(J2,請求管理!A:I,9,FALSE),0))
B12: 但し | D12: =IF(J2="","",IFERROR(VLOOKUP(J2,請求管理!A:C,3,FALSE),"")) | F12: の代金として
B14: 上記正に領収いたしました。
B16: 内訳
B17: 請求種別 | D17: =IF(J2="","",IFERROR(VLOOKUP(J2,請求管理!A:E,5,FALSE),""))
B18: 請求日 | D18: =IF(J2="","",IFERROR(VLOOKUP(J2,請求管理!A:F,6,FALSE),""))
B19: 請求額 | D19: =IF(J2="","",IFERROR(VLOOKUP(J2,請求管理!A:G,7,FALSE),0))
B20: 入金日 | D20: =IF(J2="","",IFERROR(VLOOKUP(J2,請求管理!A:H,8,FALSE),""))
B21: 入金額 | D21: =IF(J2="","",IFERROR(VLOOKUP(J2,請求管理!A:I,9,FALSE),0))
G23: 株式会社 LinK
G24: 〔社印〕

Sheet 請求管理
A1: 請求管理
A2: 株式会社LinK - 請求・入金管理
A3: ※ 案件ごとの請求・入金を行単位で追跡。分割請求（着手金/完工金）に対応。
A4: 請求ID | B4: 案件ID | C4: 案件名 | D4: 顧客名 | E4: 請求種別 | F4: 請求日 | G4: 請求額 | H4: 入金日 | I4: 入金額 | J4: 残額 | K4: ステータス | L4: 備考
A5: =IF(B5="","","INV-"&TEXT(ROW()-4,"000")) -> INV-001 | B5: P-001 | C5: =IF(B5="","",IFERROR(VLOOKUP(B5,案件管理!A:D,4,FALSE),"")) -> 吉野様邸 リフォーム工事 | D5: =IF(B5="","",IFERROR(VLOOKUP(B5,案件管理!A:C,3,FALSE),"")) -> 矢島不動産管理株式会社 | E5: 一括 | F5: 45735 | G5: 3500000 | H5: 45760 | I5: 3500000 | J5: =IF(B5="","",IF(G5="","",G5-IF(I5="",0,I5))) -> 0 | K5: =IF(B5="","",IF(G5="","",IF(J5<=0,"✅入金済",IF(I5<>"","⚠一部入金",IF(F5<>"","❌未入金",""))))) -> ✅入金済
A6: =IF(B6="","","INV-"&TEXT(ROW()-4,"000")) -> INV-002 | B6: P-003 | C6: =IF(B6="","",IFERROR(VLOOKUP(B6,案件管理!A:D,4,FALSE),"")) -> 吉野様邸 キッチンリフォーム | D6: =IF(B6="","",IFERROR(VLOOKUP(B6,案件管理!A:C,3,FALSE),"")) -> 矢島不動産管理株式会社 | E6: 着手金 | F6: 46034 | G6: 627220 | H6: 46040 | I6: 627220 | J6: =IF(B6="","",IF(G6="","",G6-IF(I6="",0,I6))) -> 0 | K6: =IF(B6="","",IF(G6="","",IF(J6<=0,"✅入金済",IF(I6<>"","⚠一部入金",IF(F6<>"","❌未入金",""))))) -> ✅入金済
A7: =IF(B7="","","INV-"&TEXT(ROW()-4,"000")) -> INV-003 | B7: P-003 | C7: =IF(B7="","",IFERROR(VLOOKUP(B7,案件管理!A:D,4,FALSE),"")) -> 吉野様邸 キッチンリフォーム | D7: =IF(B7="","",IFERROR(VLOOKUP(B7,案件管理!A:C,3,FALSE),"")) -> 矢島不動産管理株式会社 | E7: 完工金 | F7: 46064 | G7: 627220 | J7: =IF(B7="","",IF(G7="","",G7-IF(I7="",0,I7))) -> 627220 | K7: =IF(B7="","",IF(G7="","",IF(J7<=0,"✅入金済",IF(I7<>"","⚠一部入金",IF(F7<>"","❌未入金",""))))) -> ❌未入金
A8: =IF(B8="","","INV-"&TEXT(ROW()-4,"000")) | C8: =IF(B8="","",IFERROR(VLOOKUP(B8,案件管理!A:D,4,FALSE),"")) | D8: =IF(B8="","",IFERROR(VLOOKUP(B8,案件管理!A:C,3,FALSE),"")) | J8: =IF(B8="","",IF(G8="","",G8-IF(I8="",0,I8))) | K8: =IF(B8="","",IF(G8="","",IF(J8<=0,"✅入金済",IF(I8<>"","⚠一部入金",IF(F8<>"","❌未入金","")))))
A9: =IF(B9="","","INV-"&TEXT(ROW()-4,"000")) | C9: =IF(B9="","",IFERROR(VLOOKUP(B9,案件管理!A:D,4,FALSE),"")) | D9: =IF(B9="","",IFERROR(VLOOKUP(B9,案件管理!A:C,3,FALSE),"")) | J9: =IF(B9="","",IF(G9="","",G9-IF(I9="",0,I9))) | K9: =IF(B9="","",IF(G9="","",IF(J9<=0,"✅入金済",IF(I9<>"","⚠一部入金",IF(F9<>"","❌未入金","")))))
A10: =IF(B10="","","INV-"&TEXT(ROW()-4,"000")) | C10: =IF(B10="","",IFERROR(VLOOKUP(B10,案件管理!A:D,4,FALSE),"")) | D10: =IF(B10="","",IFERROR(VLOOKUP(B10,案件管理!A:C,3,FALSE),"")) | J10: =IF(B10="","",IF(G10="","",G10-IF(I10="",0,I10))) | K10: =IF(B10="","",IF(G10="","",IF(J10<=0,"✅入金済",IF(I10<>"","⚠一部入金",IF(F10<>"","❌未入金","")))))
A11: =IF(B11="","","INV-"&TEXT(ROW()-4,"000")) | C11: =IF(B11="","",IFERROR(VLOOKUP(B11,案件管理!A:D,4,FALSE),"")) | D11: =IF(B11="","",IFERROR(VLOOKUP(B11,案件管理!A:C,3,FALSE),"")) | J11: =IF(B11="","",IF(G11="","",G11-IF(I11="",0,I11))) | K11: =IF(B11="","",IF(G11="","",IF(J11<=0,"✅入金済",IF(I11<>"","⚠一部入金",IF(F11<>"","❌未入金","")))))
